Workbook
Name 結餘: #REF!

Sheet 現金流量表 (手打、整合)
D2: 現在日期 | E2: =TODAY() -> 45957
D3: 年月 | E3: 估值 | F3: 結構 | G3: 45839 | H3: =EDATE(G3,1) -> 45870 | I3: =EDATE(H3,1) -> 45901 | J3: =EDATE(I3,1) -> 45931 | K3: =EDATE(J3,1) -> 45962 | L3: =EDATE(K3,1) -> 45992 | M3: =EDATE(L3,1) -> 46023 | N3: =EDATE(M3,1) -> 46054 | O3: =EDATE(N3,1) -> 46082 | ... AV3: =EDATE(AU3,1) -> 47088
D4: 持有資金 | F4: 0 | G4: =F4+G5 -> -425 | H4: =G4+H5 -> 3100 | I4: =H4+I5 -> 2725 | J4: =I4+J5 -> -10600 | K4: =J4+K5 -> -23925 | L4: =K4+L5 -> -46250 | M4: =L4+M5 -> -54620 | N4: =M4+N5 -> 37010 | ... AV4: =AU4+AV5 -> -417480
D5: 現金流 | G5: =G6-G27-G37 -> -425 | H5: =H6-H27-H37 -> 3525 | I5: =I6-I27-I37 -> -375 | J5: =J6-J27-J37 -> -13325 | K5: =K6-K27-K37 -> -13325 | L5: =L6-L27-L37 -> -22325 | M5: =M6-M27-M37 -> -8370 | N5: =N6-N27-N37 -> 91630 | ... AV5: =AV6-AV27-AV37 -> -13081
B6: 收入 | D6: 總計 | E6: {=AVERAGE(_xlfn._xlws.FILTER(G6:AV6, $G$3:$AV$3 <= $E$2))} -> #NAME? | G6: =SUM(G7+G14+G19) -> 86244 | H6: =SUM(H7+H14+H19) -> 90194 | I6: =SUM(I7+I14+I19) -> 92694 | J6: =SUM(J7+J14+J19) -> 79744 | K6: =SUM(K7+K14+K19) -> 79744 | L6: =SUM(L7+L14+L19) -> 79744 | M6: =SUM(M7+M14+M19) -> 79744 | N6: =SUM(N7+N14+N19) -> 179744 | ... AV6: =SUM(AV7+AV14+AV19) -> 60008
D7: 工資收入 | E7: {=AVERAGE(_xlfn._xlws.FILTER(G7:AV7, $G$3:$AV$3 <= $E$2))} -> #NAME? | F7: =E7/$E$6 -> #NAME? | G7: =SUM(G8:G13) -> 86244 | H7: =SUM(H8:H13) -> 90194 | I7: =SUM(I8:I13) -> 90194 | J7: =SUM(J8:J13) -> 79744 | K7: =SUM(K8:K13) -> 79744 | L7: =SUM(L8:L13) -> 79744 | M7: =SUM(M8:M13) -> 79744 | N7: =SUM(N8:N12) -> 179744 | O7: =SUM(O8:O13) -> 79744 | P7: =SUM(P8:P13) -> 0 | Q7: =SUM(Q8:Q13) -> 0 | R7: =SUM(R8:R13) -> 360000 | S7: =SUM(S8:S13) -> 60000 | T7: =SUM(T8:T13) -> 60000 | U7: =SUM(U8:U13) -> 60000 | V7: =SUM(V8:V13) -> 60000 | ... AV7: =SUM(AV8:AV13) -> 60008
D8: 薪資 | E8: {=AVERAGE(_xlfn._xlws.FILTER(G8:AV8, $G$3:$AV$3 <= $E$2))} -> #NAME? | G8: 71244 | H8: 71244 | I8: 71244 | J8: 66244 | K8: 66244 | L8: 66244 | M8: 66244 | N8: 66244 | O8: 66244 | P8: 0 | Q8: 0 | R8: 60000 | S8: 60000 | T8: 60000 | U8: 60000 | V8: 60000 | W8: 60000 | X8: 60000 | Y8: 60000 | Z8: 60000 | AA8: 60000 | AB8: 60000 | AC8: 60000 | AD8: 60000 | AE8: 60000 | AF8: 60000 | AG8: 60000 | AH8: 60000 | AI8: 60000 | AJ8: 60000 | AK8: 60000 | AL8: 60000 | AM8: 60000 | AN8: 60000 | AO8: 60001 | AP8: 60002 | AQ8: 60003 | AR8: 60004 | AS8: 60005 | AT8: 60006 | AU8: 60007 | AV8: 60008
D9: 加班費 | E9: {=AVERAGE(_xlfn._xlws.FILTER(G9:AV9, $G$3:$AV$3 <= $E$2))} -> #NAME? | G9: 0 | H9: 18950 | I9: 18950 | J9: 13500 | K9: 13500 | L9: 13500 | M9: 13500 | N9: 13500 | O9: 13500 | P9: 0 | Q9: 0 | R9: 0 | S9: 0 | T9: 0 | U9: 0 | V9: 0 | W9: 0 | X9: 0 | Y9: 0 | Z9: 0 | AA9: 0 | AB9: 0 | AC9: 0 | AD9: 0 | AE9: 0 | AF9: 0 | AG9: 0 | AH9: 0 | AI9: 0 | AJ9: 0 | AK9: 0 | AL9: 0 | AM9: 0 | AN9: 0 | AO9: 0 | AP9: 0 | AQ9: 0 | AR9: 0 | AS9: 0 | AT9: 0 | AU9: 0 | AV9: 0
D10: 佣金(考績獎金) | E10: {=AVERAGE(_xlfn._xlws.FILTER(G10:AV10, $G$3:$AV$3 <= $E$2))} -> #NAME? | G10: 0 | H10: 0 | I10: 0 | J10: 0 | K10: 0 | L10: 0 | M10: 0 | N10: 50000 | O10: 0 | P10: 0 | Q10: 0 | R10: 0 | S10: 0 | T10: 0 | U10: 0 | V10: 0 | W10: 0 | X10: 0 | Y10: 0 | Z10: 0 | AA10: 0 | AB10: 0 | AC10: 0 | AD10: 0 | AE10: 0 | AF10: 0 | AG10: 0 | AH10: 0 | AI10: 0 | AJ10: 0 | AK10: 0 | AL10: 0 | AM10: 0 | AN10: 0 | AO10: 0 | AP10: 0 | AQ10: 0 | AR10: 0 | AS10: 0 | AT10: 0 | AU10: 0 | AV10: 0
D11: 年終獎金 | E11: {=AVERAGE(_xlfn._xlws.FILTER(G11:AV11, $G$3:$AV$3 <= $E$2))} -> #NAME? | G11: 0 | H11: 0 | I11: 0 | J11: 0 | K11: 0 | L11: 0 | M11: 0 | N11: 50000 | O11: 0 | P11: 0 | Q11: 0 | R11: 0 | S11: 0 | T11: 0 | U11: 0 | V11: 0 | W11: 0 | X11: 0 | Y11: 0 | Z11: 0 | AA11: 0 | AB11: 0 | AC11: 0 | AD11: 0 | AE11: 0 | AF11: 0 | AG11: 0 | AH11: 0 | AI11: 0 | AJ11: 0 | AK11: 0 | AL11: 0 | AM11: 0 | AN11: 0 | AO11: 0 | AP11: 0 | AQ11: 0 | AR11: 0 | AS11: 0 | AT11: 0 | AU11: 0 | AV11: 0
D12: 兼職收入 | E12: {=AVERAGE(_xlfn._xlws.FILTER(G12:AV12, $G$3:$AV$3 <= $E$2))} -> #NAME? | G12: 15000 | H12: 0 | I12: 0 | J12: 0 | K12: 0 | L12: 0 | M12: 0 | N12: 0 | O12: 0 | P12: 0 | Q12: 0 | R12: 0 | S12: 0 | T12: 0 | U12: 0 | V12: 0 | W12: 0 | X12: 0 | Y12: 0 | Z12: 0 | AA12: 0 | AB12: 0 | AC12: 0 | AD12: 0 | AE12: 0 | AF12: 0 | AG12: 0 | AH12: 0 | AI12: 0 | AJ12: 0 | AK12: 0 | AL12: 0 | AM12: 0 | AN12: 0 | AO12: 0 | AP12: 0 | AQ12: 0 | AR12: 0 | AS12: 0 | AT12: 0 | AU12: 0 | AV12: 0
D13: 其他 | E13: {=AVERAGE(_xlfn._xlws.FILTER(G13:AV13, $G$3:$AV$3 <= $E$2))} -> #NAME? | G13: 0 | H13: 0 | I13: 0 | J13: 0 | K13: 0 | L13: 0 | M13: 0 | N13: 0 | O13: 0 | P13: 0 | Q13: 0 | R13: 300000 | S13: 0 | T13: 0 | U13: 0 | V13: 0 | W13: 0 | X13: 0 | Y13: 0 | Z13: 0 | AA13: 0 | AB13: 0 | AC13: 0 | AD13: 0 | AE13: 0 | AF13: 0 | AG13: 0 | AH13: 0 | AI13: 0 | AJ13: 0 | AK13: 0 | AL13: 0 | AM13: 0 | AN13: 0 | AO13: 0 | AP13: 0 | AQ13: 0 | AR13: 0 | AS13: 0 | AT13: 0 | AU13: 0 | AV13: 0
D14: 非工資收入 | E14: {=AVERAGE(_xlfn._xlws.FILTER(G14:AV14, $G$3:$AV$3 <= $E$2))} -> #NAME? | F14: =E14/$E$6 -> #NAME? | G14: =SUM(G15:G18) -> 0 | H14: =SUM(H15:H18) -> 0 | I14: =SUM(I15:I18) -> 2500 | J14: =SUM(J15:J18) -> 0 | K14: =SUM(K15:K18) -> 0 | L14: =SUM(L15:L18) -> 0 | M14: =SUM(M15:M18) -> 0 | N14: =SUM(N15:N18) -> 0 | ... AV14: =SUM(AV15:AV18) -> 0
D15: 營利所得 | E15: {=AVERAGE(_xlfn._xlws.FILTER(G15:AV15, $G$3:$AV$3 <= $E$2))} -> #NAME? | G15: 0 | H15: 0 | I15: 0 | J15: 0 | K15: 0 | L15: 0 | M15: 0 | N15: 0 | O15: 0 | P15: 0 | Q15: 0 | R15: 0 | S15: 0 | T15: 0 | U15: 0 | V15: 0 | W15: 0 | X15: 0 | Y15: 0 | Z15: 0 | AA15: 0 | AB15: 0 | AC15: 0 | AD15: 0 | AE15: 0 | AF15: 0 | AG15: 0 | AH15: 0 | AI15: 0 | AJ15: 0 | AK15: 0 | AL15: 0 | AM15: 0 | AN15: 0 | AO15: 0 | AP15: 0 | AQ15: 0 | AR15: 0 | AS15: 0 | AT15: 0 | AU15: 0 | AV15: 0
D16: 資本利得 | E16: {=AVERAGE(_xlfn._xlws.FILTER(G16:AV16, $G$3:$AV$3 <= $E$2))} -> #NAME? | G16: 0 | H16: 0 | I16: =I36*0.1 -> 2500 | J16: =J36*0.1 -> 0 | K16: =K36*0.1 -> 0 | L16: =L36*0.1 -> 0 | M16: =M36*0.1 -> 0 | N16: =N36*0.1 -> 0 | O16: =O36*0.1 -> 0 | P16: =P36*0.1 -> 0 | ... AV16: =AV36*0.1 -> 0
D17: 人情借款 | E17: {=AVERAGE(_xlfn._xlws.FILTER(G17:AV17, $G$3:$AV$3 <= $E$2))} -> #NAME? | G17: 0 | H17: 0 | I17: 0 | J17: 0 | K17: 0 | L17: 0 | M17: 0 | N17: 0 | O17: 0 | P17: 0 | Q17: 0 | R17: 0 | S17: 0 | T17: 0 | U17: 0 | V17: 0 | W17: 0 | X17: 0 | Y17: 0 | Z17: 0 | AA17: 0 | AB17: 0 | AC17: 0 | AD17: 0 | AE17: 0 | AF17: 0 | AG17: 0 | AH17: 0 | AI17: 0 | AJ17: 0 | AK17: 0 | AL17: 0 | AM17: 0 | AN17: 0 | AO17: 0 | AP17: 0 | AQ17: 0 | AR17: 0 | AS17: 0 | AT17: 0 | AU17: 0 | AV17: 0
D18: 其他 | E18: {=AVERAGE(_xlfn._xlws.FILTER(G18:AV18, $G$3:$AV$3 <= $E$2))} -> #NAME? | G18: 0 | H18: 0 | I18: 0 | J18: 0 | K18: 0 | L18: 0 | M18: 0 | N18: 0 | O18: 0 | P18: 0 | Q18: 0 | R18: 0 | S18: 0 | T18: 0 | U18: 0 | V18: 0 | W18: 0 | X18: 0 | Y18: 0 | Z18: 0 | AA18: 0 | AB18: 0 | AC18: 0 | AD18: 0 | AE18: 0 | AF18: 0 | AG18: 0 | AH18: 0 | AI18: 0 | AJ18: 0 | AK18: 0 | AL18: 0 | AM18: 0 | AN18: 0 | AO18: 0 | AP18: 0 | AQ18: 0 | AR18: 0 | AS18: 0 | AT18: 0 | AU18: 0 | AV18: 0
D19: 被動 | E19: {=AVERAGE(_xlfn._xlws.FILTER(G19:AV19, $G$3:$AV$3 <= $E$2))} -> #NAME? | F19: =E19/$E$6 -> #NAME? | G19: =SUM(G20:G26) -> 0 | H19: =SUM(H20:H26) -> 0 | I19: =SUM(I20:I26) -> 0 | J19: =SUM(J20:J26) -> 0 | K19: =SUM(K20:K26) -> 0 | L19: =SUM(L20:L26) -> 0 | M19: =SUM(M20:M26) -> 0 | N19: =SUM(N20:N26) -> 0 | ... AV19: =SUM(AV20:AV26) -> 0
D20: 退休金 | E20: {=AVERAGE(_xlfn._xlws.FILTER(G20:AV20, $G$3:$AV$3 <= $E$2))} -> #NAME? | G20: 0 | H20: 0 | I20: 0 | J20: 0 | K20: 0 | L20: 0 | M20: 0 | N20: 0 | O20: 0 | P20: 0 | Q20: 0 | R20: 0 | S20: 0 | T20: 0 | U20: 0 | V20: 0 | W20: 0 | X20: 0 | Y20: 0 | Z20: 0 | AA20: 0 | AB20: 0 | AC20: 0 | AD20: 0 | AE20: 0 | AF20: 0 | AG20: 0 | AH20: 0 | AI20: 0 | AJ20: 0 | AK20: 0 | AL20: 0 | AM20: 0 | AN20: 0 | AO20: 0 | AP20: 0 | AQ20: 0 | AR20: 0 | AS20: 0 | AT20: 0 | AU20: 0 | AV20: 0
D21: 保險滿期金 | E21: {=AVERAGE(_xlfn._xlws.FILTER(G21:AV21, $G$3:$AV$3 <= $E$2))} -> #NAME? | G21: 0 | H21: 0 | I21: 0 | J21: 0 | K21: 0 | L21: 0 | M21: 0 | N21: 0 | O21: 0 | P21: 0 | Q21: 0 | R21: 0 | S21: 0 | T21: 0 | U21: 0 | V21: 0 | W21: 0 | X21: 0 | Y21: 0 | Z21: 0 | AA21: 0 | AB21: 0 | AC21: 0 | AD21: 0 | AE21: 0 | AF21: 0 | AG21: 0 | AH21: 0 | AI21: 0 | AJ21: 0 | AK21: 0 | AL21: 0 | AM21: 0 | AN21: 0 | AO21: 0 | AP21: 0 | AQ21: 0 | AR21: 0 | AS21: 0 | AT21: 0 | AU21: 0 | AV21: 0
D22: 跟會到期 | E22: {=AVERAGE(_xlfn._xlws.FILTER(G22:AV22, $G$3:$AV$3 <= $E$2))} -> #NAME? | G22: 0 | H22: 0 | I22: 0 | J22: 0 | K22: 0 | L22: 0 | M22: 0 | N22: 0 | O22: 0 | P22: 0 | Q22: 0 | R22: 0 | S22: 0 | T22: 0 | U22: 0 | V22: 0 | W22: 0 | X22: 0 | Y22: 0 | Z22: 0 | AA22: 0 | AB22: 0 | AC22: 0 | AD22: 0 | AE22: 0 | AF22: 0 | AG22: 0 | AH22: 0 | AI22: 0 | AJ22: 0 | AK22: 0 | AL22: 0 | AM22: 0 | AN22: 0 | AO22: 0 | AP22: 0 | AQ22: 0 | AR22: 0 | AS22: 0 | AT22: 0 | AU22: 0 | AV22: 0
D23: 利息收入 | E23: {=AVERAGE(_xlfn._xlws.FILTER(G23:AV23, $G$3:$AV$3 <= $E$2))} -> #NAME? | G23: 0 | H23: 0 | I23: 0 | J23: 0 | K23: 0 | L23: 0 | M23: 0 | N23: 0 | O23: 0 | P23: 0 | Q23: 0 | R23: 0 | S23: 0 | T23: 0 | U23: 0 | V23: 0 | W23: 0 | X23: 0 | Y23: 0 | Z23: 0 | AA23: 0 | AB23: 0 | AC23: 0 | AD23: 0 | AE23: 0 | AF23: 0 | AG23: 0 | AH23: 0 | AI23: 0 | AJ23: 0 | AK23: 0 | AL23: 0 | AM23: 0 | AN23: 0 | AO23: 0 | AP23: 0 | AQ23: 0 | AR23: 0 | AS23: 0 | AT23: 0 | AU23: 0 | AV23: 0
D24: 租金收入 | E24: {=AVERAGE(_xlfn._xlws.FILTER(G24:AV24, $G$3:$AV$3 <= $E$2))} -> #NAME? | G24: 0 | H24: 0 | I24: 0 | J24: 0 | K24: 0 | L24: 0 | M24: 0 | N24: 0 | O24: 0 | P24: 0 | Q24: 0 | R24: 0 | S24: 0 | T24: 0 | U24: 0 | V24: 0 | W24: 0 | X24: 0 | Y24: 0 | Z24: 0 | AA24: 0 | AB24: 0 | AC24: 0 | AD24: 0 | AE24: 0 | AF24: 0 | AG24: 0 | AH24: 0 | AI24: 0 | AJ24: 0 | AK24: 0 | AL24: 0 | AM24: 0 | AN24: 0 | AO24: 0 | AP24: 0 | AQ24: 0 | AR24: 0 | AS24: 0 | AT24: 0 | AU24: 0 | AV24: 0
D25: 股利 | E25: {=AVERAGE(_xlfn._xlws.FILTER(G25:AV25, $G$3:$AV$3 <= $E$2))} -> #NAME? | G25: 0 | H25: 0 | I25: 0 | J25: 0 | K25: 0 | L25: 0 | M25: 0 | N25: 0 | O25: 0 | P25: 0 | Q25: 0 | R25: 0 | S25: 0 | T25: 0 | U25: 0 | V25: 0 | W25: 0 | X25: 0 | Y25: 0 | Z25: 0 | AA25: 0 | AB25: 0 | AC25: 0 | AD25: 0 | AE25: 0 | AF25: 0 | AG25: 0 | AH25: 0 | AI25: 0 | AJ25: 0 | AK25: 0 | AL25: 0 | AM25: 0 | AN25: 0 | AO25: 0 | AP25: 0 | AQ25: 0 | AR25: 0 | AS25: 0 | AT25: 0 | AU25: 0 | AV25: 0
D26: 其他 | E26: {=AVERAGE(_xlfn._xlws.FILTER(G26:AV26, $G$3:$AV$3 <= $E$2))} -> #NAME? | G26: 0 | H26: 0 | I26: 0 | J26: 0 | K26: 0 | L26: 0 | M26: 0 | N26: 0 | O26: 0 | P26: 0 | Q26: 0 | R26: 0 | S26: 0 | T26: 0 | U26: 0 | V26: 0 | W26: 0 | X26: 0 | Y26: 0 | Z26: 0 | AA26: 0 | AB26: 0 | AC26: 0 | AD26: 0 | AE26: 0 | AF26: 0 | AG26: 0 | AH26: 0 | AI26: 0 | AJ26: 0 | AK26: 0 | AL26: 0 | AM26: 0 | AN26: 0 | AO26: 0 | AP26: 0 | AQ26: 0 | AR26: 0 | AS26: 0 | AT26: 0 | AU26: 0 | AV26: 0
B27: 理財支出 | D27: 總計 | E27: {=AVERAGE(_xlfn._xlws.FILTER(G27:AV27, $G$3:$AV$3 <= $E$2))} -> #NAME? | G27: =SUM(G28+G31+G35) -> 0 | H27: =SUM(H28+H31+H35) -> 0 | I27: =SUM(I28+I31+I35) -> 0 | J27: =SUM(J28+J31+J35) -> 0 | K27: =SUM(K28+K31+K35) -> 0 | L27: =SUM(L28+L31+L35) -> 0 | M27: =SUM(M28+M31+M35) -> 0 | N27: =SUM(N28+N31+N35) -> 0 | ... S27: =SUM(S28+S31+S35) -> 0 | T27: 0 | U27: 0 | V27: 0 | W27: 0 | X27: 0 | Y27: 0 | Z27: 0 | AA27: 0 | AB27: 0 | AC27: 0 | AD27: 0 | AE27: 0 | AF27: 0 | AG27: 0 | AH27: 0 | AI27: 0 | AJ27: 0 | AK27: 0 | AL27: 0 | AM27: 0 | AN27: 0 | AO27: 0 | AP27: 0 | AQ27: 0 | AR27: 0 | AS27: 0 | AT27: 0 | AU27: 0 | AV27: 0
D28: 緊急預備金 | E28: {=AVERAGE(_xlfn._xlws.FILTER(G28:AV28, $G$3:$AV$3 <= $E$2))} -> #NAME? | G28: 0 | H28: 0 | I28: 0 | J28: 0 | K28: 0 | L28: 0 | M28: 0 | N28: 0 | O28: 0 | P28: 0 | Q28: 0 | R28: 0 | S28: 0 | T28: 0 | U28: 0 | V28: 0 | W28: 0 | X28: 0 | Y28: 0 | Z28: 0 | AA28: 0 | AB28: 0 | AC28: 0 | AD28: 0 | AE28: 0 | AF28: 0 | AG28: 0 | AH28: 0 | AI28: 0 | AJ28: 0 | AK28: 0 | AL28: 0 | AM28: 0 | AN28: 0 | AO28: 0 | AP28: 0 | AQ28: 0 | AR28: 0 | AS28: 0 | AT28: 0 | AU28: 0 | AV28: 0
D29: 夢想基金 | E29: {=AVERAGE(_xlfn._xlws.FILTER(G29:AV29, $G$3:$AV$3 <= $E$2))} -> #NAME? | G29: 0 | H29: 0 | I29: 0 | J29: 0 | K29: 0 | L29: 0 | M29: 0 | N29: 0 | O29: 0 | P29: 0 | Q29: 0 | R29: 0 | S29: 0 | T29: 0 | U29: 0 | V29: 0 | W29: 0 | X29: 0 | Y29: 0 | Z29: 0 | AA29: 0 | AB29: 0 | AC29: 0 | AD29: 0 | AE29: 0 | AF29: 0 | AG29: 0 | AH29: 0 | AI29: 0 | AJ29: 0 | AK29: 0 | AL29: 0 | AM29: 0 | AN29: 0 | AO29: 0 | AP29: 0 | AQ29: 0 | AR29: 0 | AS29: 0 | AT29: 0 | AU29: 0 | AV29: 0
D30: 退休基金 | E30: {=AVERAGE(_xlfn._xlws.FILTER(G30:AV30, $G$3:$AV$3 <= $E$2))} -> #NAME? | G30: 0 | H30: 0 | I30: 0 | J30: 0 | K30: 0 | L30: 0 | M30: 0 | N30: 0 | O30: 0 | P30: 0 | Q30: 0 | R30: 0 | S30: 0 | T30: 0 | U30: 0 | V30: 0 | W30: 0 | X30: 0 | Y30: 0 | Z30: 0 | AA30: 0 | AB30: 0 | AC30: 0 | AD30: 0 | AE30: 0 | AF30: 0 | AG30: 0 | AH30: 0 | AI30: 0 | AJ30: 0 | AK30: 0 | AL30: 0 | AM30: 0 | AN30: 0 | AO30: 0 | AP30: 0 | AQ30: 0 | AR30: 0 | AS30: 0 | AT30: 0 | AU30: 0 | AV30: 0
D31: 投資資金 | E31: {=AVERAGE(_xlfn._xlws.FILTER(G31:AV31, $G$3:$AV$3 <= $E$2))} -> #NAME? | G31: 0 | H31: 0 | I31: 0 | J31: 0 | K31: 0 | L31: 0 | M31: 0 | N31: 0 | O31: 0 | P31: 0 | Q31: 0 | R31: 0 | S31: 0 | T31: 0 | U31: 0 | V31: 0 | W31: 0 | X31: 0 | Y31: 0 | Z31: 0 | AA31: 0 | AB31: 0 | AC31: 0 | AD31: 0 | AE31: 0 | AF31: 0 | AG31: 0 | AH31: 0 | AI31: 0 | AJ31: 0 | AK31: =EDATE(AJ31,1) -> 31 | AL31: =EDATE(AK31,1) -> 59 | AM31: =EDATE(AL31,1) -> 88 | AN31: =EDATE(AM31,1) -> 119 | AO31: =EDATE(AN31,1) -> 149 | AP31: =EDATE(AO31,1) -> 180 | AQ31: =EDATE(AP31,1) -> 210 | AR31: =EDATE(AQ31,1) -> 241 | ... AV31: =EDATE(AU31,1) -> 363
D32: 教育基金 | E32: {=AVERAGE(_xlfn._xlws.FILTER(G32:AV32, $G$3:$AV$3 <= $E$2))} -> #NAME? | G32: 0 | H32: 0 | I32: 0 | J32: 0 | K32: 0 | L32: 0 | M32: 0 | N32: 0 | O32: 0 | P32: 0 | Q32: 0 | R32: 0 | S32: 0 | T32: 0 | U32: 0 | V32: 0 | W32: 0 | X32: 0 | Y32: 0 | Z32: 0 | AA32: 0 | AB32: 0 | AC32: 0 | AD32: 0 | AE32: 0 | AF32: 0 | AG32: 0 | AH32: 0 | AI32: 0 | AJ32: 0 | AK32: 0 | AL32: 0 | AM32: 0 | AN32: 0 | AO32: 0 | AP32: 0 | AQ32: 0 | AR32: 0 | AS32: 0 | AT32: 0 | AU32: 0 | AV32: 0
D33: 其他 | E33: {=AVERAGE(_xlfn._xlws.FILTER(G33:AV33, $G$3:$AV$3 <= $E$2))} -> #NAME? | G33: 0 | H33: 0 | I33: 0 | J33: 0 | K33: 0 | L33: 0 | M33: 0 | N33: 0 | O33: 0 | P33: 0 | Q33: 0 | R33: 0 | S33: 0 | T33: 0 | U33: 0 | V33: 0 | W33: 0 | X33: 0 | Y33: 0 | Z33: 0 | AA33: 0 | AB33: 0 | AC33: 0 | AD33: 0 | AE33: 0 | AF33: 0 | AG33: 0 | AH33: 0 | AI33: 0 | AJ33: 0 | AK33: 0 | AL33: 0 | AM33: 0 | AN33: 0 | AO33: 0 | AP33: 0 | AQ33: 0 | AR33: 0 | AS33: 0 | AT33: 0 | AU33: 0 | AV33: 0
E34: {=AVERAGE(_xlfn._xlws.FILTER(G34:AV34, $G$3:$AV$3 <= $E$2))} -> #NAME? | G34: 0 | H34: 0 | I34: 0 | J34: 0 | K34: 0 | L34: 0 | M34: 0 | N34: 0 | O34: 0 | P34: 0 | Q34: 0 | R34: 0 | S34: 0 | T34: 0 | U34: 0 | V34: 0 | W34: 0 | X34: 0 | Y34: 0 | Z34: 0 | AA34: 0 | AB34: 0 | AC34: 0 | AD34: 0 | AE34: 0 | AF34: 0 | AG34: 0 | AH34: 0 | AI34: 0 | AJ34: 0 | AK34: 0 | AL34: 0 | AM34: 0 | AN34: 0 | AO34: 0 | AP34: 0 | AQ34: 0 | AR34: 0 | AS34: 0 | AT34: 0 | AU34: 0 | AV34: 0
E35: {=AVERAGE(_xlfn._xlws.FILTER(G35:AV35, $G$3:$AV$3 <= $E$2))} -> #NAME? | G35: 0 | H35: 0 | I35: 0 | J35: 0 | K35: 0 | L35: 0 | M35: 0 | N35: 0 | O35: 0 | P35: 0 | Q35: 0 | R35: 0 | S35: 0 | T35: 0 | U35: 0 | V35: 0 | W35: 0 | X35: 0 | Y35: 0 | Z35: 0 | AA35: 0 | AB35: 0 | AC35: 0 | AD35: 0 | AE35: 0 | AF35: 0 | AG35: 0 | AH35: 0 | AI35: 0 | AJ35: 0 | AK35: 0 | AL35: 0 | AM35: 0 | AN35: 0 | AO35: 0 | AP35: 0 | AQ35: 0 | AR35: 0 | AS35: 0 | AT35: 0 | AU35: 0 | AV35: 0
E36: {=AVERAGE(_xlfn._xlws.FILTER(G36:AV36, $G$3:$AV$3 <= $E$2))} -> #NAME? | G36: 0 | H36: 0 | I36: 25000 | J36: 0 | K36: 0 | L36: 0 | M36: 0 | N36: 0 | O36: 0 | P36: 0 | Q36: 0 | R36: 0 | S36: 0 | T36: 0 | U36: 0 | V36: 0 | W36: 0 | X36: 0 | Y36: 0 | Z36: 0 | AA36: 0 | AB36: 0 | AC36: 0 | AD36: 0 | AE36: 0 | AF36: 0 | AG36: 0 | AH36: 0 | AI36: 0 | AJ36: 0 | AK36: 0 | AL36: 0 | AM36: 0 | AN36: 0 | AO36: 0 | AQ36: 0 | AR36: 0 | AT36: 0 | AU36: 0 | AV36: 0
D37: 總計 | E37: {=AVERAGE(_xlfn._xlws.FILTER(G37:AV37, $G$3:$AV$3 <= $E$2))} -> #NAME? | G37: =SUM(G38+G41+G45+G53+G60+G70+G81+G87+G93+G96+G99) -> 86669 | H37: =SUM(H38+H41+H45+H53+H60+H70+H81+H87+H93+H96+H99) -> 86669 | I37: =SUM(I38+I41+I45+I53+I60+I70+I81+I87+I93+I96+I99) -> 93069 | J37: =SUM(J38+J41+J45+J53+J60+J70+J81+J87+J93+J96+J99) -> 93069 | K37: =SUM(K38+K41+K45+K53+K60+K70+K81+K87+K93+K96+K99) -> 93069 | L37: =SUM(L38+L41+L45+L53+L60+L70+L81+L87+L93+L96+L99) -> 102069 | M37: =SUM(M38+M41+M45+M53+M60+M70+M81+M87+M93+M96+M99) -> 88114 | N37: =SUM(N38+N41+N45+N53+N60+N70+N81+N87+N93+N96+N99) -> 88114 | ... AV37: =SUM(AV38+AV41+AV45+AV53+AV60+AV70+AV81+AV87+AV93+AV96+AV99) -> 73089
B38: 支出 | C38: 必要支出 | D38: 食 | E38: {=AVERAGE(_xlfn._xlws.FILTER(G38:AV38, $G$3:$AV$3 <= $E$2))} -> #NAME? | G38: =SUM(G39:G40) -> 0 | H38: =SUM(H39:H40) -> 0 | I38: =SUM(I39:I40) -> 0 | J38: =SUM(J39:J40) -> 0 | K38: =SUM(K39:K40) -> 0 | L38: =SUM(L39:L40) -> 0 | M38: =SUM(M39:M40) -> 0 | N38: =SUM(N39:N40) -> 0 | ... AV38: =SUM(AV39:AV40) -> 0
D39: 外食 | E39: {=AVERAGE(_xlfn._xlws.FILTER(G39:AV39, $G$3:$AV$3 <= $E$2))} -> #NAME? | G39: 0 | H39: 0 | I39: 0 | J39: 0 | K39: 0 | L39: 0 | M39: 0 | N39: 0 | O39: 0 | P39: 0 | Q39: 0 | R39: 0 | S39: 0 | T39: 0 | U39: 0 | V39: 0 | W39: 0 | X39: 0 | Y39: 0 | Z39: 0 | AA39: 0 | AB39: 0 | AC39: 0 | AD39: 0 | AE39: 0 | AF39: 0 | AG39: 0 | AH39: 0 | AI39: 0 | AJ39: 0 | AK39: 0 | AL39: 0 | AM39: 0 | AN39: 0 | AO39: 0 | AP39: 0 | AQ39: 0 | AR39: 0 | AS39: 0 | AT39: 0 | AU39: 0 | AV39: 0
D40: 食材 | E40: {=AVERAGE(_xlfn._xlws.FILTER(G40:AV40, $G$3:$AV$3 <= $E$2))} -> #NAME? | G40: 0 | H40: 0 | I40: 0 | J40: 0 | K40: 0 | L40: 0 | M40: 0 | N40: 0 | O40: 0 | P40: 0 | Q40: 0 | R40: 0 | S40: 0 | T40: 0 | U40: 0 | V40: 0 | W40: 0 | X40: 0 | Y40: 0 | Z40: 0 | AA40: 0 | AB40: 0 | AC40: 0 | AD40: 0 | AE40: 0 | AF40: 0 | AG40: 0 | AH40: 0 | AI40: 0 | AJ40: 0 | AK40: 0 | AL40: 0 | AM40: 0 | AN40: 0 | AO40: 0 | AP40: 0 | AQ40: 0 | AR40: 0 | AS40: 0 | AT40: 0 | AU40: 0 | AV40: 0
D41: 衣 | E41: {=AVERAGE(_xlfn._xlws.FILTER(G41:AV41, $G$3:$AV$3 <= $E$2))} -> #NAME? | G41: 0 | H41: 0 | I41: =SUM(I42:I44) -> 0 | J41: =SUM(J42:J44) -> 0 | K41: =SUM(K42:K44) -> 0 | L41: =SUM(L42:L44) -> 0 | M41: =SUM(M42:M44) -> 0 | N41: =SUM(N42:N44) -> 0 | O41: =SUM(O42:O44) -> 0 | P41: =SUM(P42:P44) -> 0 | ... AV41: =SUM(AV42:AV44) -> 0
...

Sheet DASHBOARD

Sheet Resources
B1: 顏色 | C1: 位置 | D1: 傾斜角度 | E1: Transparency | G1: Shadow | H1: 50 | I1: 100 | J1: 40 | K1: 135 | L1: 15
B2: #3883D4 | C2: 0 | D2: 70 | H2: 20 | I2: 100 | J2: 15 | K2: 135 | L2: 8
B3: #224192 | C3: 75 | D3: 70
B5: #21509A | C5: 0 | D5: 135
B6: #0F2453 | C6: 55 | D6: 135
A7: LINE | B7: #6494DA | C7: 0 | D7: 90
A8: LINE | B8: #BCC6FF | C8: 50 | D8: 90
A9: LINE | B9: #2F6EC7 | C9: 95 | D9: 90
B11: #2F6EC7 | C11: 0 | D11: 45
B12: #224E9F | C12: 85 | D12: 45
A13: LINE | B13: #6494DA | C13: 0 | D13: 90
A14: LINE | B14: #BCC6FF | C14: 75 | D14: 90
A15: LINE | B15: #2F6EC7 | C15: 100 | D15: 90
B17: #1C4285 | C17: 0 | D17: 45
B18: #132D64 | C18: 85 | D18: 45
A19: LINE | B19: #6494DA | C19: 0 | D19: 90
A20: LINE | B20: #BCC6FF | C20: 85 | D20: 90
A21: LINE | B21: #2F6EC7 | C21: 95 | D21: 90
B23: #15306A | C23: 0 | D23: 45
B24: #13295E | C24: 85 | D24: 45
A25: LINE | B25: #6494DA | C25: 0 | D25: 90
A26: LINE | B26: #BCC6FF | C26: 75 | D26: 90
A27: LINE | B27: #2F6EC7 | C27: 100 | D27: 90

Sheet 評估表
B2: LIFE評估表
C3: 目標 | D3: 公式 | F3: 平衡航道 | G3: 現況 | H3: 缺口 | L3: 細項說明
B4: LAUCH(啟動) | C4: 沒有壓榨性債務(利率>8%) | D4: 月收入* | E4: 0 | F4: ='現金流量表(連動)'!$E$5*E4 -> 0 | G4: =資產負債表!C33 -> 3435680 | H4: =G4-F4 -> 3435680 | J4: *3-5年達成 | K4: *債務利息不要超過通膨2% | L4: 其他個人財產
B5: 淨資產<年收入50% | C5: 現金準備(活期存款) | D5: 月收入* | E5: 1 | F5: ='現金流量表(連動)'!$E$5*E5 -> 76000 | G5: =資產負債表!C4 -> 10000 | H5: =G5-F5 -> -66000 | J5: *儲蓄率平均每年18% | K5: *儲蓄存款用於應急支出 | L5: 其他資產
B6: =資產負債表!K2/('現金流量表(連動)'!E5*12) -> 0.15350877 | C6: 投資收益 | D6: 月收入* | E6: 1 | F6: ='現金流量表(連動)'!$E$5*E6 -> 76000 | G6: =資產負債表!Q13+資產負債表!Q16 -> 20000 | H6: =G6-F6 -> -56000 | J6: *不要有購屋念頭 | K6: *活期存款用於日常支出 | L6: 生息資產
C7: 現金準備(儲蓄存款) | D7: 月收入* | E7: 2 | F7: ='現金流量表(連動)'!$E$5*E7 -> 152000 | G7: =資產負債表!C5 -> 0 | H7: =G7-F7 -> -152000 | J7: *通常佔據人生3-5年 | L7: 投資收益
B8: INDEPENDENCE(獨立) | C8: 沒有壓榨性債務(利率>10%) | D8: 月收入* | E8: 0 | F8: ='現金流量表(連動)'!$E$5*E8 -> 0 | G8: =資產負債表!C33 -> 3435680 | H8: =G8-F8 -> 3435680 | J8: *負債比<65% | L8: 外匯
B9: 淨資產=年收入50%-200% | C9: 現金準備(活期存款) | D9: 月收入* | E9: 3 | F9: ='現金流量表(連動)'!$E$5*E9 -> 228000 | G9: =資產負債表!C4 -> 10000 | H9: =G9-F9 -> -218000 | J9: *自住屋需考慮住至少7年 | L9: 期貨
B10: =資產負債表!K2/('現金流量表(連動)'!E5*12) -> 0.15350877 | C10: 現金準備(儲蓄存款) | D10: 月收入* | E10: 3 | F10: ='現金流量表(連動)'!$E$5*E10 -> 228000 | G10: =資產負債表!C5 -> 0 | H10: =G10-F10 -> -228000 | J10: *每個小孩增加儲蓄率2% | L10: 長期收益
C11: 投資收益 | D11: 月收入* | E11: 6 | F11: ='現金流量表(連動)'!$E$5*E11 -> 456000 | G11: =資產負債表!Q13+資產負債表!Q16 -> 20000 | H11: =G11-F11 -> -436000 | L11: 股票
C12: 改變人生(購屋頭期款、辭職準備金) | D12: 月收入* | E12: 9 | F12: ='現金流量表(連動)'!$E$5*E12 -> 684000 | G12: =資產負債表!C7 -> 0 | H12: =G12-F12 -> -684000 | L12: 基金
C13: 淨資產 | D13: 月收入* | E13: 21 | F13: ='現金流量表(連動)'!$E$5*E13 -> 1596000 | G13: =SUM(G9:G12) -> 30000 | H13: =G13-F13 -> -1566000 | L13: 債券
C14: 總負債 | D14: 月收入* | E14: 39 | F14: ='現金流量表(連動)'!$E$5*E14 -> 2964000 | G14: =資產負債表!K21 -> 3435680 | H14: =G14-F14 -> 471680 | L14: 事業股份
C15: 總資產 | D15: 月收入* | E15: 60 | F15: ='現金流量表(連動)'!$E$5*E15 -> 4560000 | G15: =資產負債表!K2 -> 140000 | H15: =G15-F15 -> -4420000 | L15: 投資不動產
B16: FREEDOM(自由) | C16: 沒有壓榨性債務(利率>10%) | D16: 月收入* | E16: 0 | F16: ='現金流量表(連動)'!$E$5*E16 -> 0 | G16: =資產負債表!C33 -> 3435680 | H16: =G16-F16 -> 3435680 | J16: *負債比<40% | L16: 改變人生
B17: 淨資產=年收入200%-500% | C17: 現金準備(活期存款+儲蓄存款) | D17: 月收入* | E17: 5 | F17: ='現金流量表(連動)'!$E$5*E17 -> 380000 | G17: =資產負債表!Q3 -> 10000 | H17: =G17-F17 -> -370000 | J17: *降低債務比例為主(增加資產) | L17: 銀行定存
B18: =資產負債表!K2/('現金流量表(連動)'!E5*12) -> 0.15350877 | C18: 其他個人財產 | D18: 月收入* | E18: 5 | F18: ='現金流量表(連動)'!$E$5*E18 -> 380000 | G18: =其他資產[[#Totals],[價值]]+資產負債表!M19 -> 110000 | H18: =G18-F18 -> -270000 | J18: *通常佔據人生10-15年 | L18: 壓榨性債務
C19: 投資收益 | D19: 月收入* | E19: 15 | F19: ='現金流量表(連動)'!$E$5*E19 -> 1140000 | G19: =資產負債表!Q13 -> 20000 | H19: =G19-F19 -> -1120000 | J19: *退休儲蓄:長期投資=6:4 | L19: 高利息貸款
C20: 長期收益 | D20: 月收入* | E20: 25 | F20: ='現金流量表(連動)'!$E$5*E20 -> 1900000 | G20: =資產負債表!Q16 -> 0 | H20: =G20-F20 -> -1900000 | J20: *淨財富超過月收入*60，再考慮清償債務 | L20: 信用卡
C21: 總負債 | D21: 月收入* | E21: 40 | F21: ='現金流量表(連動)'!$E$5*E21 -> 3040000 | G21: =資產負債表!K21 -> 3435680 | H21: =G21-F21 -> 395680 | L21: 功能性債務
C22: 淨財富 | D22: 月收入* | E22: 65 | F22: ='現金流量表(連動)'!$E$5*E22 -> 4940000 | G22: =G23-G21 -> -3295680 | H22: =G22-F22 -> -8235680 | L22: 車貸
C23: 總資產 | D23: 月收入* | E23: 105 | F23: ='現金流量表(連動)'!$E$5*E23 -> 7980000 | G23: =資產負債表!K2 -> 140000 | H23: =G23-F23 -> -7840000 | L23: 房貸
B24: EQUILIBRIUM(均衡) | C24: 沒有壓榨性債務(利率>10%) | D24: 月收入* | E24: 0 | F24: ='現金流量表(連動)'!$E$5*E24 -> 0 | G24: =資產負債表!C33 -> 3435680 | H24: =G24-F24 -> 3435680 | J24: 負債比<25% | L24: 致富性債務
B25: 淨資產=年收入500%- | C25: 現金準備(活期存款+儲蓄存款) | D25: 月收入* | E25: 7 | F25: ='現金流量表(連動)'!$E$5*E25 -> 532000 | G25: =資產負債表!Q3 -> 10000 | H25: =G25-F25 -> -522000 | J25: 是當持有債務，有利於未來發展 | L25: 自用不動產抵押貸款
B26: =資產負債表!K2/('現金流量表(連動)'!E5*12) -> 0.15350877 | C26: 其他個人財產 | D26: 月收入* | E26: 7 | F26: ='現金流量表(連動)'!$E$5*E26 -> 532000 | G26: =其他資產[[#Totals],[價值]]+資產負債表!M19 -> 110000 | H26: =G26-F26 -> -422000 | L26: 投資性不動產抵押貸款
C27: 總負債 | D27: 月收入* | E27: 35 | F27: ='現金流量表(連動)'!$E$5*E27 -> 2660000 | G27: =資產負債表!K21 -> 3435680 | H27: =G27-F27 -> 775680 | L27: 信用貸款
C28: 投資收益 | D28: 月收入* | E28: 56 | F28: ='現金流量表(連動)'!$E$5*E28 -> 4256000 | G28: =資產負債表!Q13 -> 20000 | H28: =G28-F28 -> -4236000 | L28: 分期付款
C29: 長期收益 | D29: 月收入* | E29: 91 | F29: ='現金流量表(連動)'!$E$5*E29 -> 6916000 | G29: =資產負債表!Q16 -> 0 | H29: =G29-F29 -> -6916000 | L29: 保單貸款
C30: 總投資資產 | D30: 月收入* | E30: 147 | F30: ='現金流量表(連動)'!$E$5*E30 -> 11172000 | G30: =G28+G29 -> 20000 | H30: =G30-F30 -> -11152000
B32: 總負債 | C32: =資產負債表!K21 -> 3435680
B33: 基準單位=總負債/8 | C33: =C32/8 -> 429460
B36: FREEDOM(自由) | C36: 沒有壓榨性債務(利率>10%) | D36: 基準單位* | E36: 0 | F36: =$C$33*E36 -> 0 | G36: =資產負債表!C49 -> 0 | H36: =G36-F36 -> 0
B37: 淨資產=年收入200%-500% | C37: 現金準備(活期存款+儲蓄存款) | D37: 基準單位* | E37: 1 | F37: =$C$33*E37 -> 429460 | G37: =資產負債表!Q19 -> 0 | H37: =G37-F37 -> -429460
B38: =資產負債表!K2/('現金流量表(連動)'!E5*12) -> 0.15350877 | C38: 其他個人財產 | D38: 基準單位* | E38: 1 | F38: =$C$33*E38 -> 429460 | G38: =其他資產[[#Totals],[價值]]+資產負債表!M35 -> 110000 | H38: =G38-F38 -> -319460
C39: 投資收益 | D39: 基準單位* | E39: 3 | F39: =$C$33*E39 -> 1288380 | G39: =資產負債表!Q29 -> 24.540571 | H39: =G39-F39 -> -1288355.5
C40: 長期收益 | D40: 基準單位* | E40: 5 | F40: =$C$33*E40 -> 2147300 | G40: =資產負債表!Q32 -> 0 | H40: =G40-F40 -> -2147300
C41: 總負債 | D41: 基準單位* | E41: 8 | F41: =$C$33*E41 -> 3435680 | G41: =資產負債表!K37 -> 0 | H41: =G41-F41 -> -3435680
C42: 淨財富 | D42: 基準單位* | E42: 13 | F42: =$C$33*E42 -> 5582980 | G42: =G43-G41 -> 0 | H42: =G42-F42 -> -5582980
C43: 總資產 | D43: 基準單位* | E43: 21 | F43: =$C$33*E43 -> 9018660 | G43: =資產負債表!K18 -> 0 | H43: =G43-F43 -> -9018660
B44: EQUILIBRIUM(均衡) | C44: 沒有壓榨性債務(利率>10%) | D44: 基準單位* | E44: 0 | F44: =$C$33*E44 -> 0 | G44: =資產負債表!C49 -> 0 | H44: =G44-F44 -> 0
...

Sheet 收入規劃
B2: 預算規劃
B4: 概要 | D4: 1 | E4: 2 | F4: 3 | G4: 4 | H4: 5 | I4: 6 | J4: 7 | K4: 8 | L4: 9 | M4: 10 | N4: 11 | O4: 12 | P4: Total | Q4: Avg
B5: 總收入 | D5: =D10+D19+D26 -> 84505 | E5: =E10+E19+E26 -> 0 | F5: =F10+F19+F26 -> 0 | G5: =G10+G19+G26 -> 0 | H5: =H10+H19+H26 -> 0 | I5: =I10+I19+I26 -> 0 | J5: =J10+J19+J26 -> 0 | K5: =K10+K19+K26 -> 0 | ... O5: =O10+O19+O26 -> 0 | P5: =SUM(D5:O5) -> 84505 | Q5: =P5/COLUMNS(D5:O5) -> 7042.0833
B6: 總支出 | D6: =支出規劃!D6 -> 0 | E6: =支出規劃!E6 -> 0 | F6: =支出規劃!F6 -> 0 | G6: =支出規劃!G6 -> 0 | H6: =支出規劃!H6 -> 0 | I6: =支出規劃!I6 -> 0 | J6: =支出規劃!J6 -> 0 | K6: =支出規劃!K6 -> 0 | ... O6: =支出規劃!O6 -> 0 | P6: =SUM(D6:O6) -> 0 | Q6: =P6/COLUMNS(D6:O6) -> 0
B7: 淨額 | D7: =D5-D6 -> 84505 | E7: =E5-E6 -> 0 | F7: =F5-F6 -> 0 | G7: =G5-G6 -> 0 | H7: =H5-H6 -> 0 | I7: =I5-I6 -> 0 | J7: =J5-J6 -> 0 | K7: =K5-K6 -> 0 | ... O7: =O5-O6 -> 0 | P7: =SUM(D7:O7) -> 84505 | Q7: =P7/COLUMNS(D7:O7) -> 7042.0833
B9: 工資收入 | D9: =D$4 -> 1 | E9: =E$4 -> 2 | F9: =F$4 -> 3 | G9: =G$4 -> 4 | H9: =H$4 -> 5 | I9: =I$4 -> 6 | J9: =J$4 -> 7 | K9: =K$4 -> 8 | ... O9: =O$4 -> 12 | P9: Total | Q9: Avg
B10: 總 | D10: =SUM(D11:D16) -> 79000 | E10: =SUM(E11:E16) -> 0 | F10: =SUM(F11:F16) -> 0 | G10: =SUM(G11:G16) -> 0 | H10: =SUM(H11:H16) -> 0 | I10: =SUM(I11:I16) -> 0 | J10: =SUM(J11:J16) -> 0 | K10: =SUM(K11:K16) -> 0 | ... Q10: =SUM(Q11:Q16) -> 6583.3333
B11: 薪資 | D11: 60000 | P11: =SUM(D11:O11) -> 60000 | Q11: =P11/COLUMNS(D11:O11) -> 5000
B12: 加班費 | D12: 19000 | P12: =SUM(D12:O12) -> 19000 | Q12: =P12/COLUMNS(D12:O12) -> 1583.3333
B13: 佣金(考績獎金) | P13: =SUM(D13:O13) -> 0 | Q13: =P13/COLUMNS(D13:O13) -> 0
B14: 年終獎金 | P14: =SUM(D14:O14) -> 0 | Q14: =P14/COLUMNS(D14:O14) -> 0
B15: 兼職收入 | P15: =SUM(D15:O15) -> 0 | Q15: =P15/COLUMNS(D15:O15) -> 0
B16: 其他 | P16: =SUM(D16:O16) -> 0 | Q16: =P16/COLUMNS(D16:O16) -> 0
B18: 非工資收入 | D18: =D$4 -> 1 | E18: =E$4 -> 2 | F18: =F$4 -> 3 | G18: =G$4 -> 4 | H18: =H$4 -> 5 | I18: =I$4 -> 6 | J18: =J$4 -> 7 | K18: =K$4 -> 8 | ... O18: =O$4 -> 12 | P18: Total | Q18: Avg
B19: 總 | D19: =SUM(D20:D23) -> 5500 | E19: =SUM(E20:E23) -> 0 | F19: =SUM(F20:F23) -> 0 | G19: =SUM(G20:G23) -> 0 | H19: =SUM(H20:H23) -> 0 | I19: =SUM(I20:I23) -> 0 | J19: =SUM(J20:J23) -> 0 | K19: =SUM(K20:K23) -> 0 | ... Q19: =SUM(Q20:Q23) -> 458.33333
B20: 營利所得 | D20: 5500 | P20: =SUM(D20:O20) -> 5500 | Q20: =P20/COLUMNS(D20:O20) -> 458.33333
B21: 資本利得 | P21: =SUM(D21:O21) -> 0 | Q21: =P21/COLUMNS(D21:O21) -> 0
B22: 人情借款 | P22: =SUM(D22:O22) -> 0 | Q22: =P22/COLUMNS(D22:O22) -> 0
B23: 其他 | P23: =SUM(D23:O23) -> 0 | Q23: =P23/COLUMNS(D23:O23) -> 0
B25: 被動收入 | D25: =D$4 -> 1 | E25: =E$4 -> 2 | F25: =F$4 -> 3 | G25: =G$4 -> 4 | H25: =H$4 -> 5 | I25: =I$4 -> 6 | J25: =J$4 -> 7 | K25: =K$4 -> 8 | ... O25: =O$4 -> 12 | P25: Total | Q25: Avg
B26: 總 | D26: =SUM(D27:D33) -> 5 | E26: =SUM(E27:E33) -> 0 | F26: =SUM(F27:F33) -> 0 | G26: =SUM(G27:G33) -> 0 | H26: =SUM(H27:H33) -> 0 | I26: =SUM(I27:I33) -> 0 | J26: =SUM(J27:J33) -> 0 | K26: =SUM(K27:K33) -> 0 | ... Q26: =SUM(Q27:Q33) -> 0.41666667
B27: 退休金 | P27: =SUM(D27:O27) -> 0 | Q27: =P27/COLUMNS(D27:O27) -> 0
B28: 保險滿期金 | P28: =SUM(D28:O28) -> 0 | Q28: =P28/COLUMNS(D28:O28) -> 0
B29: 跟會到期 | P29: =SUM(D29:O29) -> 0 | Q29: =P29/COLUMNS(D29:O29) -> 0
B30: 利息收入 | D30: 5 | P30: =SUM(D30:O30) -> 5 | Q30: =P30/COLUMNS(D30:O30) -> 0.41666667
B31: 租金收入 | P31: =SUM(D31:O31) -> 0 | Q31: =P31/COLUMNS(D31:O31) -> 0
B32: 股利
B33: 其他 | P33: =SUM(D33:O33) -> 0 | Q33: =P33/COLUMNS(D33:O33) -> 0
B35: 蓄水池分配 | D35: =D$4 -> 1 | E35: =E$4 -> 2 | F35: =F$4 -> 3 | G35: =G$4 -> 4 | H35: =H$4 -> 5 | I35: =I$4 -> 6 | J35: =J$4 -> 7 | K35: =K$4 -> 8 | ... O35: =O$4 -> 12 | P35: Total | Q35: Avg | R35: 收入占比
B36: 現金池 | C36: 必要支出（NEC） | D36: =$D$5*R36 -> 46477.75 | E36: =$D$5*SUMPRODUCT(K64:N64,$K$63:$N$63) -> 8450.5 | F36: =$D$5*T36 -> 0 | G36: =$D$5*U36 -> 0 | H36: =$D$5*V36 -> 0 | I36: =$D$5*W36 -> 0 | J36: =$D$5*X36 -> 0 | K36: =$D$5*Y36 -> 0 | L36: =$D$5*Z36 -> 0 | M36: =$D$5*AA36 -> 0 | ... O36: =$D$5*AC36 -> 0 | P36: =SUM(D36:O36) -> 54928.25 | Q36: =P36/COLUMNS(D36:O36) -> 4577.3542 | R36: 0.55
B37: 預備金池 | C37: 長期儲蓄（LTS） | D37: =$D$5*R37 -> 8450.5 | E37: =$D$5*SUMPRODUCT(K65:N65,$K$63:$N$63) -> 21126.25 | F37: =$D$5*T38 -> 0 | G37: =$D$5*U38 -> 0 | H37: =$D$5*V38 -> 0 | I37: =$D$5*W38 -> 0 | J37: =$D$5*X38 -> 0 | K37: =$D$5*Y38 -> 0 | L37: =$D$5*Z38 -> 0 | M37: =$D$5*AA38 -> 0 | ... O37: =$D$5*AC38 -> 0 | P37: =SUM(D37:O38) -> 29576.75 | Q37: =P37/COLUMNS(D37:O38) -> 2464.7292 | R37: 0.1
B38: 夢想池
B39: 投資池 | C39: 財務自由（FFA） | D39: =$D$5*R39 -> 8450.5 | E39: =$D$5*SUMPRODUCT(K66:N66,$K$63:$N$63) -> 27886.65 | F39: =$D$5*T39 -> 0 | G39: =$D$5*U39 -> 0 | H39: =$D$5*V39 -> 0 | I39: =$D$5*W39 -> 0 | J39: =$D$5*X39 -> 0 | K39: =$D$5*Y39 -> 0 | L39: =$D$5*Z39 -> 0 | M39: =$D$5*AA39 -> 0 | ... O39: =$D$5*AC39 -> 0 | P39: =SUM(D39:O39) -> 36337.15 | Q39: =P39/COLUMNS(D39:O39) -> 3028.0958 | R39: 0.1
C40: 教育成長（EDU） | D40: =$D$5*R40 -> 8450.5 | E40: =$D$5*SUMPRODUCT(K67:N67,$K$63:$N$63) -> 3380.2 | F40: =$D$5*T40 -> 0 | G40: =$D$5*U40 -> 0 | H40: =$D$5*V40 -> 0 | I40: =$D$5*W40 -> 0 | J40: =$D$5*X40 -> 0 | K40: =$D$5*Y40 -> 0 | L40: =$D$5*Z40 -> 0 | M40: =$D$5*AA40 -> 0 | ... O40: =$D$5*AC40 -> 0 | P40: =SUM(D40:O40) -> 11830.7 | Q40: =P40/COLUMNS(D40:O40) -> 985.89167 | R40: 0.1
C41: 玩樂享受（PLY） | D41: =$D$5*R41 -> 8450.5 | E41: =$D$5*SUMPRODUCT(K68:N68,$K$63:$N$63) -> 3380.2 | F41: =$D$5*T41 -> 0 | G41: =$D$5*U41 -> 0 | H41: =$D$5*V41 -> 0 | I41: =$D$5*W41 -> 0 | J41: =$D$5*X41 -> 0 | K41: =$D$5*Y41 -> 0 | L41: =$D$5*Z41 -> 0 | M41: =$D$5*AA41 -> 0 | ... O41: =$D$5*AC41 -> 0 | P41: =SUM(D41:O41) -> 11830.7 | Q41: =P41/COLUMNS(D41:O41) -> 985.89167 | R41: 0.1
C42: 慈善（GIV） | D42: =$D$5*R42 -> 4225.25 | E42: =$D$5*SUMPRODUCT(K69:N69,$K$63:$N$63) -> 20281.2 | F42: =$D$5*T42 -> 0 | G42: =$D$5*U42 -> 0 | H42: =$D$5*V42 -> 0 | I42: =$D$5*W42 -> 0 | J42: =$D$5*X42 -> 0 | K42: =$D$5*Y42 -> 0 | L42: =$D$5*Z42 -> 0 | M42: =$D$5*AA42 -> 0 | ... O42: =$D$5*AC42 -> 0 | P42: =SUM(D42:O42) -> 24506.45 | Q42: =P42/COLUMNS(D42:O42) -> 2042.2042 | R42: 0.05
C43: 總 | D43: =SUM(D39:D42) -> 29576.75 | E43: =SUM(E39:E42) -> 54928.25 | F43: =SUM(F39:F42) -> 0 | G43: =SUM(G39:G42) -> 0 | H43: =SUM(H39:H42) -> 0 | I43: =SUM(I39:I42) -> 0 | J43: =SUM(J39:J42) -> 0 | K43: =SUM(K39:K42) -> 0 | ... O43: =SUM(O39:O42) -> 0 | P43: =SUM(D43:O43) -> 84505 | Q43: =P43/COLUMNS(D43:O43) -> 7042.0833 | R43: =SUM(R39:R42) -> 0.35
B44: 總 | D44: =SUM(D36:D42) -> 84505 | E44: =SUM(E36:E42) -> 84505 | F44: =SUM(F36:F42) -> 0 | G44: =SUM(G36:G42) -> 0 | H44: =SUM(H36:H42) -> 0 | I44: =SUM(I36:I42) -> 0 | J44: =SUM(J36:J42) -> 0 | K44: =SUM(K36:K42) -> 0 | ... R44: =SUM(R36:R42) -> 1
B46: 投資池分配 | D46: =D$4 -> 1 | E46: =E$4 -> 2 | F46: =F$4 -> 3 | G46: =G$4 -> 4 | H46: =H$4 -> 5 | I46: =I$4 -> 6 | J46: =J$4 -> 7 | K46: =K$4 -> 8 | ... O46: =O$4 -> 12 | P46: Total | Q46: Avg | R46: 資金占比
B47: 短期 | D47: =SUM(D$39:D$42)*$R47 -> 8873.025 | E47: =SUM(E$39:E$42)*$R47 -> 16478.475 | F47: =SUM(F$39:F$42)*$R47 -> 0 | G47: =SUM(G$39:G$42)*$R47 -> 0 | H47: =SUM(H$39:H$42)*$R47 -> 0 | I47: =SUM(I$39:I$42)*$R47 -> 0 | J47: =SUM(J$39:J$42)*$R47 -> 0 | K47: =SUM(K$39:K$42)*$R47 -> 0 | ... O47: =SUM(O$39:O$42)*$R47 -> 0 | P47: =SUM(D47:O47) -> 25351.5 | Q47: =P47/COLUMNS(D47:O47) -> 2112.625 | R47: 0.3
...

Sheet 支出規劃
B2: 預算規劃
B4: 概要 | D4: 1 | E4: 2 | F4: 3 | G4: 4 | H4: 5 | I4: 6 | J4: 7 | K4: 8 | L4: 9 | M4: 10 | N4: 11 | O4: 12 | P4: Total | Q4: Avg
B5: 總收入 | D5: =收入規劃!D5 -> 84505 | E5: =收入規劃!E5 -> 0 | F5: =收入規劃!F5 -> 0 | G5: =收入規劃!G5 -> 0 | H5: =收入規劃!H5 -> 0 | I5: =收入規劃!I5 -> 0 | J5: =收入規劃!J5 -> 0 | K5: =收入規劃!K5 -> 0 | ... O5: =收入規劃!O5 -> 0 | P5: =SUM(D5:O5) -> 84505 | Q5: =P5/COLUMNS(D5:O5) -> 7042.0833
B6: 總支出 | D6: =D10+D16+D23+D35+D69+D92+D101+D53+D77+D110+D118+D45+D62+D130 -> 0 | E6: =E10+E16+E23+E35+E69+E92+E101+E53+E77+E110+E118+E45+E62+E130 -> 0 | F6: =F10+F16+F23+F35+F69+F92+F101+F53+F77+F110+F118+F45+F62+F130 -> 0 | G6: =G10+G16+G23+G35+G69+G92+G101+G53+G77+G110+G118+G45+G62+G130 -> 0 | H6: =H10+H16+H23+H35+H69+H92+H101+H53+H77+H110+H118+H45+H62+H130 -> 0 | I6: =I10+I16+I23+I35+I69+I92+I101+I53+I77+I110+I118+I45+I62+I130 -> 0 | J6: =J10+J16+J23+J35+J69+J92+J101+J53+J77+J110+J118+J45+J62+J130 -> 0 | K6: =K10+K16+K23+K35+K69+K92+K101+K53+K77+K110+K118+K45+K62+K130 -> 0 | ... O6: =O10+O16+O23+O35+O69+O92+O101+O53+O77+O110+O118+O45+O62+O130 -> 0 | P6: =SUM(D6:O6) -> 0 | Q6: =P6/COLUMNS(D6:O6) -> 0
B7: 淨額 | D7: =D5-D6 -> 84505 | E7: =E5-E6 -> 0 | F7: =F5-F6 -> 0 | G7: =G5-G6 -> 0 | H7: =H5-H6 -> 0 | I7: =I5-I6 -> 0 | J7: =J5-J6 -> 0 | K7: =K5-K6 -> 0 | ... O7: =O5-O6 -> 0 | P7: =SUM(D7:O7) -> 84505 | Q7: =P7/COLUMNS(D7:O7) -> 7042.0833
B9: 食 | D9: =D$4 -> 1 | E9: =E$4 -> 2 | F9: =F$4 -> 3 | G9: =G$4 -> 4 | H9: =H$4 -> 5 | I9: =I$4 -> 6 | J9: =J$4 -> 7 | K9: =K$4 -> 8 | ... O9: =O$4 -> 12 | P9: Total | Q9: Avg
B10: 總 | D10: =SUM(D11:D12) -> 0 | E10: =SUM(E11:E12) -> 0 | F10: =SUM(F11:F12) -> 0 | G10: =SUM(G11:G12) -> 0 | H10: =SUM(H11:H12) -> 0 | I10: =SUM(I11:I12) -> 0 | J10: =SUM(J11:J12) -> 0 | K10: =SUM(K11:K12) -> 0 | ... Q10: =SUM(Q11:Q12) -> 0
B11: 外食 | P11: =SUM(D11:O11) -> 0 | Q11: =P11/COLUMNS(D11:O11) -> 0
B12: 食材
B13: 佔總支出百分比 | D13: =IF(D$6=0," - ",D10/D$6) -> - | E13: =IF(E$6=0," - ",E10/E$6) -> - | F13: =IF(F$6=0," - ",F10/F$6) -> - | G13: =IF(G$6=0," - ",G10/G$6) -> - | H13: =IF(H$6=0," - ",H10/H$6) -> - | I13: =IF(I$6=0," - ",I10/I$6) -> - | J13: =IF(J$6=0," - ",J10/J$6) -> - | K13: =IF(K$6=0," - ",K10/K$6) -> - | ... Q13: =IF(Q$6=0," - ",Q10/Q$6) -> -
B15: 衣 | D15: =D$4 -> 1 | E15: =E$4 -> 2 | F15: =F$4 -> 3 | G15: =G$4 -> 4 | H15: =H$4 -> 5 | I15: =I$4 -> 6 | J15: =J$4 -> 7 | K15: =K$4 -> 8 | ... O15: =O$4 -> 12 | P15: Total | Q15: Avg
B16: 總 | D16: =SUM(D17:D19) -> 0 | E16: =SUM(E17:E19) -> 0 | F16: =SUM(F17:F19) -> 0 | G16: =SUM(G17:G19) -> 0 | H16: =SUM(H17:H19) -> 0 | I16: =SUM(I17:I19) -> 0 | J16: =SUM(J17:J19) -> 0 | K16: =SUM(K17:K19) -> 0 | ... Q16: =SUM(Q17:Q19) -> 0
B17: 治裝 | P17: =SUM(D17:O17) -> 0 | Q17: =P17/COLUMNS(D17:O17) -> 0
B18: 美容美髮 | P18: =SUM(D18:O18) -> 0 | Q18: =P18/COLUMNS(D18:O18) -> 0
B19: 衣物送洗 | P19: =SUM(D19:O19) -> 0 | Q19: =P19/COLUMNS(D19:O19) -> 0
B20: 佔總支出百分比 | D20: =IF(D$6=0," - ",D16/D$6) -> - | E20: =IF(E$6=0," - ",E16/E$6) -> - | F20: =IF(F$6=0," - ",F16/F$6) -> - | G20: =IF(G$6=0," - ",G16/G$6) -> - | H20: =IF(H$6=0," - ",H16/H$6) -> - | I20: =IF(I$6=0," - ",I16/I$6) -> - | J20: =IF(J$6=0," - ",J16/J$6) -> - | K20: =IF(K$6=0," - ",K16/K$6) -> - | ... Q20: =IF(Q$6=0," - ",Q16/Q$6) -> -
B22: 住 | D22: =D$4 -> 1 | E22: =E$4 -> 2 | F22: =F$4 -> 3 | G22: =G$4 -> 4 | H22: =H$4 -> 5 | I22: =I$4 -> 6 | J22: =J$4 -> 7 | K22: =K$4 -> 8 | ... O22: =O$4 -> 12 | P22: Total | Q22: Avg
B23: 總 | D23: =SUM(D24:D31) -> 0 | E23: =SUM(E24:E31) -> 0 | F23: =SUM(F24:F31) -> 0 | G23: =SUM(G24:G31) -> 0 | H23: =SUM(H24:H31) -> 0 | I23: =SUM(I24:I31) -> 0 | J23: =SUM(J24:J31) -> 0 | K23: =SUM(K24:K31) -> 0 | ... Q23: =SUM(Q24:Q31) -> 0
B24: 抵押貸款/租金 | P24: =SUM(D24:O24) -> 0 | Q24: =P24/COLUMNS(D24:O24) -> 0
B25: 電 | P25: =SUM(D25:O25) -> 0 | Q25: =P25/COLUMNS(D25:O25) -> 0
B26: 天然氣/瓦斯 | P26: =SUM(D26:O26) -> 0 | Q26: =P26/COLUMNS(D26:O26) -> 0
B27: 水 | P27: =SUM(D27:O27) -> 0 | Q27: =P27/COLUMNS(D27:O27) -> 0
B28: 有線/衛星/網路 | P28: =SUM(D28:O28) -> 0 | Q28: =P28/COLUMNS(D28:O28) -> 0
B29: 家具/家電 | P29: =SUM(D29:O29) -> 0 | Q29: =P29/COLUMNS(D29:O29) -> 0
B30: 家居用品 | P30: =SUM(D30:O30) -> 0 | Q30: =P30/COLUMNS(D30:O30) -> 0
B31: 其他 | P31: =SUM(D31:O31) -> 0 | Q31: =P31/COLUMNS(D31:O31) -> 0
B32: 佔總支出百分比 | D32: =IF(D$6=0," - ",D23/D$6) -> - | E32: =IF(E$6=0," - ",E23/E$6) -> - | F32: =IF(F$6=0," - ",F23/F$6) -> - | G32: =IF(G$6=0," - ",G23/G$6) -> - | H32: =IF(H$6=0," - ",H23/H$6) -> - | I32: =IF(I$6=0," - ",I23/I$6) -> - | J32: =IF(J$6=0," - ",J23/J$6) -> - | K32: =IF(K$6=0," - ",K23/K$6) -> - | ... Q32: =IF(Q$6=0," - ",Q23/Q$6) -> -
B34: 行 | D34: =D$4 -> 1 | E34: =E$4 -> 2 | F34: =F$4 -> 3 | G34: =G$4 -> 4 | H34: =H$4 -> 5 | I34: =I$4 -> 6 | J34: =J$4 -> 7 | K34: =K$4 -> 8 | ... O34: =O$4 -> 12 | P34: Total | Q34: Avg
B35: 總 | D35: =SUM(D36:D41) -> 0 | E35: =SUM(E36:E41) -> 0 | F35: =SUM(F36:F41) -> 0 | G35: =SUM(G36:G41) -> 0 | H35: =SUM(H36:H41) -> 0 | I35: =SUM(I36:I41) -> 0 | J35: =SUM(J36:J41) -> 0 | K35: =SUM(K36:K41) -> 0 | ... Q35: =SUM(Q36:Q41) -> 0
B36: 停車費 | P36: =SUM(D36:O36) -> 0 | Q36: =P36/COLUMNS(D36:O36) -> 0
B37: 加油費 | P37: =SUM(D37:O37) -> 0 | Q37: =P37/COLUMNS(D37:O37) -> 0
B38: 過路費 | P38: =SUM(D38:O38) -> 0 | Q38: =P38/COLUMNS(D38:O38) -> 0
B39: 保養 | P39: =SUM(D39:O39) -> 0 | Q39: =P39/COLUMNS(D39:O39) -> 0
B40: 大眾交通 | P40: =SUM(D40:O40) -> 0 | Q40: =P40/COLUMNS(D40:O40) -> 0
B41: 其他 | P41: =SUM(D41:O41) -> 0 | Q41: =P41/COLUMNS(D41:O41) -> 0
B42: 佔總支出百分比 | D42: =IF(D$6=0," - ",D35/D$6) -> - | E42: =IF(E$6=0," - ",E35/E$6) -> - | F42: =IF(F$6=0," - ",F35/F$6) -> - | G42: =IF(G$6=0," - ",G35/G$6) -> - | H42: =IF(H$6=0," - ",H35/H$6) -> - | I42: =IF(I$6=0," - ",I35/I$6) -> - | J42: =IF(J$6=0," - ",J35/J$6) -> - | K42: =IF(K$6=0," - ",K35/K$6) -> - | ... Q42: =IF(Q$6=0," - ",Q35/Q$6) -> -
B44: 政府規費 | D44: =D$4 -> 1 | E44: =E$4 -> 2 | F44: =F$4 -> 3 | G44: =G$4 -> 4 | H44: =H$4 -> 5 | I44: =I$4 -> 6 | J44: =J$4 -> 7 | K44: =K$4 -> 8 | ... O44: =O$4 -> 12 | P44: Total | Q44: Avg
B45: 總 | D45: =SUM(D46:D49) -> 0 | E45: =SUM(E46:E49) -> 0 | F45: =SUM(F46:F49) -> 0 | G45: =SUM(G46:G49) -> 0 | H45: =SUM(H46:H49) -> 0 | I45: =SUM(I46:I49) -> 0 | J45: =SUM(J46:J49) -> 0 | K45: =SUM(K46:K49) -> 0 | ... Q45: =SUM(Q46:Q49) -> 0
B46: 所得稅 | P46: =SUM(D46:O46) -> 0 | Q46: =P46/COLUMNS(D46:O46) -> 0
B47: 牌照稅 | P47: =SUM(D47:O47) -> 0 | Q47: =P47/COLUMNS(D47:O47) -> 0
...

Sheet 記帳區
A1: 帳戶 | B1: 幣種 | C1: 記錄類型 | D1: 主類別 | E1: 子類別 | F1: 金額 | G1: 手續費 | H1: 折扣 | I1: 名稱 | J1: 商家 | K1: 日期 | L1: 時間 | M1: 專案 | N1: 描述 | O1: 標籤 | P1: 對象
A2: 錢包 | B2: TWD | C2: 收入 | D2: 工資收入 | E2: 薪資 | F2: 71244 | G2: 0 | H2: 0 | K2: 45839 | L2: 0.775
A3: 錢包 | B3: TWD | C3: 支出 | D3: 理財支出 | E3: 活期存款 | F3: -10000 | G3: 0 | H3: 0 | K3: 45839 | L3: 0.775
A4: 錢包 | B4: TWD | C4: 支出 | D4: 食 | E4: 外食 | F4: -250 | G4: 0 | H4: 0 | K4: 45841 | L4: 0.62430556 | M4: 生活開銷
A5: 錢包 | B5: TWD | C5: 支出 | D5: 貸款 | E5: 功能性債務 | F5: -6000 | G5: 0 | H5: 0 | K5: 45842 | L5: 0.45625 | M5: 生活開銷
A6: 錢包 | B6: TWD | C6: 支出 | D6: 貸款 | E6: 功能性債務 | F6: -3000 | G6: 0 | H6: 0 | K6: 45843 | L6: 0.41458333 | M6: 生活開銷
A7: 錢包 | B7: TWD | C7: 支出 | D7: 行 | E7: 加油費 | F7: -1340 | G7: 0 | H7: 0 | K7: 45844 | L7: 0.62222222 | M7: 生活開銷
A8: 錢包 | B8: TWD | C8: 支出 | D8: 貸款 | E8: 壓榨性債務 | F8: -5177 | G8: 0 | H8: 0 | K8: 45845 | L8: 0.25763889
A9: 錢包 | B9: TWD | C9: 支出 | D9: 貸款 | E9: 壓榨性債務 | F9: -29911 | G9: 0 | H9: 0 | K9: 45846 | L9: 0.775
A10: 錢包 | B10: TWD | C10: 支出 | D10: 貸款 | E10: 壓榨性債務 | F10: -1456 | G10: 0 | H10: 0 | K10: 45847 | L10: 0.13611111 | M10: 生活開銷
A11: 錢包 | B11: TWD | C11: 支出 | D11: 貸款 | E11: 壓榨性債務 | F11: -2937 | G11: 0 | H11: 0 | K11: 45848 | L11: 0.25763889 | M11: 生活開銷
A12: 錢包 | B12: TWD | C12: 支出 | D12: 貸款 | E12: 壓榨性債務 | F12: -7800 | G12: 0 | H12: 0 | K12: 45849 | L12: 0.13680556 | M12: 生活開銷
A13: 錢包 | B13: TWD | C13: 支出 | D13: 貸款 | E13: 壓榨性債務 | F13: -23128 | G13: 0 | H13: 0 | K13: 45850 | L13: 0.64375 | M13: 生活開銷
A14: 錢包 | B14: TWD | C14: 支出 | D14: 貸款 | E14: 壓榨性債務 | F14: -7260 | G14: 0 | H14: 0 | K14: 45851 | L14: 0.41944444 | M14: 生活開銷
A15: 錢包 | B15: TWD | C15: 支出 | D15: 住 | E15: 日常用品 | F15: -130 | G15: 0 | H15: 0 | I15: 名片冊 | K15: 45852 | L15: 0.55833333 | M15: 生活開銷
A16: 錢包 | B16: TWD | C16: 支出 | D16: 食 | E16: 食材 | F16: -50 | G16: 0 | H16: 0 | K16: 45853 | L16: 0.55902778 | M16: 生活開銷
A17: 錢包 | B17: TWD | C17: 支出 | D17: 行 | E17: 火車 | F17: -1190 | G17: 0 | H17: 0 | K17: 45854 | L17: 0.13888889 | M17: 生活開銷
A18: 錢包 | B18: TWD | C18: 支出 | D18: 食 | E18: 食材 | F18: -124 | G18: 0 | H18: 0 | K18: 45855 | L18: 0.13680556 | M18: 生活開銷
A19: 錢包 | B19: TWD | C19: 收入 | D19: 工資收入 | E19: 加班費 | F19: 15000 | G19: 0 | H19: 0 | K19: 45866 | L19: 0.13819444 | M19: 生活開銷
A20: 錢包 | B20: TWD | C20: 收入 | D20: 工資收入 | E20: 薪資 | F20: 71244 | G20: 0 | H20: 0 | K20: 45870 | L20: 0.775
A21: 錢包 | B21: TWD | C21: 支出 | D21: 貸款 | E21: 功能性債務 | F21: -6000 | G21: 0 | H21: 0 | K21: 45871 | L21: 0.13611111 | M21: 生活開銷
A22: 錢包 | B22: TWD | C22: 支出 | D22: 貸款 | E22: 功能性債務 | F22: -3000 | G22: 0 | H22: 0 | K22: 45872 | L22: 0.13680556 | M22: 生活開銷
A23: 錢包 | B23: TWD | C23: 支出 | D23: 貸款 | E23: 壓榨性債務 | F23: -5177 | G23: 0 | H23: 0 | K23: 45873 | L23: 0.70902778 | M23: 生活開銷
A24: 錢包 | B24: TWD | C24: 支出 | D24: 貸款 | E24: 壓榨性債務 | F24: -29911 | G24: 0 | H24: 0 | K24: 45874 | L24: 0.71180556 | M24: 生活開銷
A25: 錢包 | B25: TWD | C25: 支出 | D25: 貸款 | E25: 壓榨性債務 | F25: -1456 | G25: 0 | H25: 0 | K25: 45875 | L25: 0.46527778 | M25: 生活開銷
A26: 錢包 | B26: TWD | C26: 支出 | D26: 貸款 | E26: 壓榨性債務 | F26: -2937 | G26: 0 | H26: 0 | K26: 45876 | L26: 0.71041667 | M26: 生活開銷
A27: 錢包 | B27: TWD | C27: 支出 | D27: 貸款 | E27: 壓榨性債務 | F27: -7800 | G27: 0 | H27: 0 | K27: 45877 | L27: 0.71041667 | M27: 生活開銷
A28: 錢包 | B28: TWD | C28: 支出 | D28: 貸款 | E28: 壓榨性債務 | F28: -23128 | G28: 0 | H28: 0 | K28: 45878 | L28: 0.775
A29: 錢包 | B29: TWD | C29: 收入 | D29: 人情 | E29: 借款 | F29: 20000 | G29: 0 | H29: 0 | K29: 45879 | L29: 0.39166667 | M29: 生活開銷
A30: 錢包 | B30: TWD | C30: 支出 | D30: 貸款 | E30: 壓榨性債務 | F30: -7260 | G30: 0 | H30: 0 | K30: 45880 | L30: 0.43333333 | M30: 生活開銷
A31: 錢包 | B31: TWD | C31: 支出 | D31: 投資 | E31: 外匯 | F31: -20000 | G31: 0 | H31: 0 | K31: 45880 | L31: 0.39583333
A32: 錢包 | B32: TWD | C32: 支出 | D32: 食 | E32: 外食 | F32: -45 | G32: 0 | H32: 0 | K32: 45881 | L32: 0.56041667 | M32: 生活開銷
A33: 錢包 | B33: TWD | C33: 支出 | D33: 食 | E33: 外食 | F33: -349 | G33: 0 | H33: 0 | K33: 45882 | L33: 0.74513889 | M33: 生活開銷
A34: 錢包 | B34: TWD | C34: 支出 | D34: 醫療 | E34: 醫療保健 | F34: -1450 | G34: 0 | H34: 0 | K34: 45883 | L34: 0.39444444 | M34: 生活開銷
A35: 錢包 | B35: TWD | C35: 支出 | D35: 食 | E35: 外食 | F35: -114 | G35: 0 | H35: 0 | K35: 45884 | L35: 0.29652778 | M35: 生活開銷
A36: 錢包 | B36: TWD | C36: 收入 | D36: 工資收入 | E36: 加班費 | F36: 15000 | G36: 0 | H36: 0 | K36: 45885 | L36: 0.29652778 | M36: 生活開銷
A37: 錢包 | B37: TWD | C37: 收入 | D37: 工資收入 | E37: 薪資 | F37: 71244 | G37: 0 | H37: 0 | K37: 45536 | L37: 0.4625 | M37: 生活開銷
A38: 錢包 | B38: TWD | C38: 支出 | D38: 貸款 | E38: 功能性債務 | F38: -6000 | G38: 0 | H38: 0 | K38: 45537 | L38: 0.46319444 | M38: 生活開銷
A39: 錢包 | B39: TWD | C39: 支出 | D39: 貸款 | E39: 功能性債務 | F39: -3000 | G39: 0 | H39: 0 | K39: 45538 | L39: 0.13611111 | M39: 生活開銷
A40: 錢包 | B40: TWD | C40: 支出 | D40: 貸款 | E40: 壓榨性債務 | F40: -5177 | G40: 0 | H40: 0 | K40: 45539 | L40: 0.13680556 | M40: 生活開銷
...

Sheet 資產負債表
B2: 資產 | J2: 總值 | K2: =流動性資產[[#Totals],[價值]]+流動性投資[[#Totals],[價值]]+非流動性投資[[#Totals],[價值]]+自用不動產[[#Totals],[價值]]+其他資產[[#Totals],[價值]]+M19 -> 140000 | P2: 資產結構
B3: 流動性資產 | C3: 價值 | D3: 佔比 | F3: 流動性投資 | G3: 價值 | H3: 佔比 | J3: 其他資產 | K3: 價值 | L3: 佔比 | P3: 日常消費(10%) | Q3: =C4+C5 -> 10000
B4: 活期存款 | C4: =-SUMIFS(記帳區!$F:$F,記帳區!$E:$E,$B4) -> 10000 | D4: =IFERROR(流動性資產[[#This Row],[價值]]/流動性資產[[#Totals],[價值]],0) -> 1 | F4: 期貨 | G4: =-SUMIFS(記帳區!$F:$F,記帳區!$E:$E,$F4) -> 0 | H4: =IFERROR(流動性投資[[#This Row],[價值]]/流動性投資[[#Totals],[價值]],0) -> 0 | J4: 車輛 | K4: 110000 | L4: =IFERROR(其他資產[[#This Row],[價值]]/其他資產[[#Totals],[價值]],0) -> 1 | P4: 活期存款
B5: 儲蓄存款 | C5: =-SUMIFS(記帳區!$F:$F,記帳區!$E:$E,$B5) -> 0 | D5: =IFERROR(流動性資產[[#This Row],[價值]]/流動性資產[[#Totals],[價值]],0) -> 0 | F5: 外匯 | G5: =-SUMIFS(記帳區!$F:$F,記帳區!$E:$E,$F5) -> 20000 | H5: =IFERROR(流動性投資[[#This Row],[價值]]/流動性投資[[#Totals],[價值]],0) -> 1 | J5: 黃金 | K5: 0 | L5: =IFERROR(其他資產[[#This Row],[價值]]/其他資產[[#Totals],[價值]],0) -> 0 | P5: 儲蓄存款
B6: 壽險 | C6: =-SUMIFS(記帳區!$F:$F,記帳區!$E:$E,$B6) -> 0 | D6: =IFERROR(流動性資產[[#This Row],[價值]]/流動性資產[[#Totals],[價值]],0) -> 0 | F6: 基金 | G6: =-SUMIFS(記帳區!$F:$F,記帳區!$E:$E,$F6) -> 0 | H6: =IFERROR(流動性投資[[#This Row],[價值]]/流動性投資[[#Totals],[價值]],0) -> 0 | J6: 收藏品 | K6: 0 | L6: =IFERROR(其他資產[[#This Row],[價值]]/其他資產[[#Totals],[價值]],0) -> 0 | P6: 保障帳戶(20％) | Q6: =C6++C7+C8+K8 -> 0
B7: 銀行定存 | C7: =-SUMIFS(記帳區!$F:$F,記帳區!$E:$E,$B7) -> 0 | D7: =IFERROR(流動性資產[[#This Row],[價值]]/流動性資產[[#Totals],[價值]],0) -> 0 | F7: 債券 | G7: =-SUMIFS(記帳區!$F:$F,記帳區!$E:$E,$F7) -> 0 | H7: =IFERROR(流動性投資[[#This Row],[價值]]/流動性投資[[#Totals],[價值]],0) -> 0 | J7: 珠寶 | K7: 0 | L7: =IFERROR(其他資產[[#This Row],[價值]]/其他資產[[#Totals],[價值]],0) -> 0 | P7: 壽險
B8: 儲蓄險 | C8: =-SUMIFS(記帳區!$F:$F,記帳區!$E:$E,$B8) -> 0 | D8: =IFERROR(流動性資產[[#This Row],[價值]]/流動性資產[[#Totals],[價值]],0) -> 0 | F8: 股票 | G8: =-SUMIFS(記帳區!$F:$F,記帳區!$E:$E,$F8) -> 0 | H8: =IFERROR(流動性投資[[#This Row],[價值]]/流動性投資[[#Totals],[價值]],0) -> 0 | J8: 保險 | K8: 0 | L8: =IFERROR(其他資產[[#This Row],[價值]]/其他資產[[#Totals],[價值]],0) -> 0 | P8: 銀行定存
B9: 其他 | C9: =-SUMIFS(記帳區!$F:$F,記帳區!$E:$E,$B9) -> 0 | D9: =IFERROR(流動性資產[[#This Row],[價值]]/流動性資產[[#Totals],[價值]],0) -> 0 | F9: 其他 | G9: =-SUMIFS(記帳區!$F:$F,記帳區!$E:$E,$F9) -> 0 | H9: =IFERROR(流動性投資[[#This Row],[價值]]/流動性投資[[#Totals],[價值]],0) -> 0 | J9: 其他 | K9: 0 | L9: =IFERROR(其他資產[[#This Row],[價值]]/其他資產[[#Totals],[價值]],0) -> 0 | P9: 儲蓄險
B10: 合計 | C10: =SUBTOTAL(109,[價值]) -> 10000 | F10: 合計 | G10: =SUBTOTAL(109,[價值]) -> 20000 | J10: 合計 | K10: =SUBTOTAL(109,[價值]) -> 110000
P12: 保險
B13: 自用不動產 | C13: 價值 | D13: 佔比 | F13: 非流動性投資 | G13: 價值 | H13: 佔比 | J13: 升息資產 | K13: 價值 | L13: 佔比 | P13: 投資收益帳戶(30%) | Q13: =G4+G5 -> 20000
B14: 住宅 | C14: 0 | D14: =IFERROR(自用不動產[[#This Row],[價值]]/自用不動產[[#Totals],[價值]],0) -> 0 | F14: 事業股份 | G14: 0 | H14: =IFERROR(非流動性投資[[#This Row],[價值]]/非流動性投資[[#Totals],[價值]],0) -> 0 | J14: 存貨 | K14: 0 | L14: =IFERROR(升息資產[[#This Row],[價值]]/升息資產[[#Totals],[價值]],0) -> 0 | P14: 外匯
B15: 辦公室 | C15: 0 | D15: =IFERROR(自用不動產[[#This Row],[價值]]/自用不動產[[#Totals],[價值]],0) -> 0 | F15: 投資不動產 | G15: 0 | H15: =IFERROR(非流動性投資[[#This Row],[價值]]/非流動性投資[[#Totals],[價值]],0) -> 0 | J15: 其他 | K15: 0 | L15: =IFERROR(升息資產[[#This Row],[價值]]/升息資產[[#Totals],[價值]],0) -> 0 | P15: 期貨
B16: 工廠 | C16: 0 | D16: =IFERROR(自用不動產[[#This Row],[價值]]/自用不動產[[#Totals],[價值]],0) -> 0 | F16: 股票(未上市) | G16: 0 | H16: =IFERROR(非流動性投資[[#This Row],[價值]]/非流動性投資[[#Totals],[價值]],0) -> 0 | L16: =IFERROR(升息資產[[#This Row],[價值]]/升息資產[[#Totals],[價值]],0) -> 0 | P16: 長期收益帳戶(40%) | Q16: =G6+G7+G8+G14+G15 -> 0
B17: 其他 | C17: 0 | D17: =IFERROR(自用不動產[[#This Row],[價值]]/自用不動產[[#Totals],[價值]],0) -> 0 | F17: 其他 | G17: 0 | H17: =IFERROR(非流動性投資[[#This Row],[價值]]/非流動性投資[[#Totals],[價值]],0) -> 0 | L17: =IFERROR(升息資產[[#This Row],[價值]]/升息資產[[#Totals],[價值]],0) -> 0 | P17: 股票
C18: 0 | D18: =IFERROR(自用不動產[[#This Row],[價值]]/自用不動產[[#Totals],[價值]],0) -> 0 | H18: =IFERROR(非流動性投資[[#This Row],[價值]]/非流動性投資[[#Totals],[價值]],0) -> 0 | L18: =IFERROR(升息資產[[#This Row],[價值]]/升息資產[[#Totals],[價值]],0) -> 0 | P18: 基金
B19: 合計 | C19: =SUBTOTAL(109,[價值]) -> 0 | F19: 合計 | G19: =SUBTOTAL(109,[價值]) -> 0 | J19: 合計 | K19: =SUBTOTAL(109,[價值]) -> 0 | P19: 債券
P20: 事業股份
B21: 負債 | J21: 總值 | K21: =壓榨性債務[[#Totals],[價值]]+功能性債務[[#Totals],[價值]] -> 3435680 | P21: 投資不動產
B22: 壓榨性債務 | C22: 價值 | D22: 佔比 | E22: 月繳 | F22: 到期日 | J22: 功能性債務 | K22: 價值 | L22: 佔比
B23: 聯邦信用卡(16.07%) | C23: 72230 | D23: =IFERROR(壓榨性債務[[#This Row],[價值]]/壓榨性債務[[#Totals],[價值]],0) -> 0.021023495 | E23: 6000 | J23: 車貸 | K23: 0 | L23: =IFERROR(功能性債務[[#This Row],[價值]]/功能性債務[[#Totals],[價值]],0) -> 0 | R23: 理想值
B24: 星展信用卡(15.89%) | C24: 7887 | D24: =IFERROR(壓榨性債務[[#This Row],[價值]]/壓榨性債務[[#Totals],[價值]],0) -> 0.0022956154 | E24: 3000 | J24: 房貸 | K24: 0 | L24: =IFERROR(功能性債務[[#This Row],[價值]]/功能性債務[[#Totals],[價值]],0) -> 0 | P24: ●短期償債能力強弱： | Q24: =流動性資產[[#Totals],[價值]]/壓榨性債務[[#Totals],[價值]] -> 0.002910632 | R24: ≧100%
B25: 中信信貸(14.78%) | C25: 252574 | D25: =IFERROR(壓榨性債務[[#This Row],[價值]]/壓榨性債務[[#Totals],[價值]],0) -> 0.073514996 | E25: 5177 | F25: 48111 | J25: 商品分期 | K25: 0 | L25: =IFERROR(功能性債務[[#This Row],[價值]]/功能性債務[[#Totals],[價值]],0) -> 0 | P25: 1.若數據<100%，生活容易陷入
B26: 中信信貸(14.78%) | C26: 1459626 | D26: =IFERROR(壓榨性債務[[#This Row],[價值]]/壓榨性債務[[#Totals],[價值]],0) -> 0.42484341 | E26: 29911 | F26: 48111 | L26: =IFERROR(功能性債務[[#This Row],[價值]]/功能性債務[[#Totals],[價值]],0) -> 0 | P26: 週轉不靈的窘境。
B27: 星展信貸(5.99%) | C27: 31553 | D27: =IFERROR(壓榨性債務[[#This Row],[價值]]/壓榨性債務[[#Totals],[價值]],0) -> 0.009183917 | E27: 1456 | F27: 46568 | L27: =IFERROR(功能性債務[[#This Row],[價值]]/功能性債務[[#Totals],[價值]],0) -> 0 | P27: 2.歐美的數據設定為≧1.5
B28: 樂分期 | C28: 17622 | D28: =IFERROR(壓榨性債務[[#This Row],[價值]]/壓榨性債務[[#Totals],[價值]],0) -> 0.0051291156 | E28: 2937 | F28: 46016 | J28: 合計 | K28: =SUBTOTAL(109,[價值]) -> 0
B29: 裕富分期 | C29: 66700 | D29: =IFERROR(壓榨性債務[[#This Row],[價值]]/壓榨性債務[[#Totals],[價值]],0) -> 0.019413915 | E29: 7800 | F29: 46104 | P29: ●負債比例大小： | Q29: =K21/K2 -> 24.540571 | R29: ≦50%
B30: 車貸 | C30: 1295168 | D30: =IFERROR(壓榨性債務[[#This Row],[價值]]/壓榨性債務[[#Totals],[價值]],0) -> 0.37697574 | E30: 23128 | F30: 47547 | J30: 致富性債務 | K30: 價值 | L30: 佔比 | P30: 1.若數據>50%，容易造成生
B31: 和潤機車 | C31: 232320 | D31: =IFERROR(壓榨性債務[[#This Row],[價值]]/壓榨性債務[[#Totals],[價值]],0) -> 0.067619802 | E31: 7260 | F31: 46693 | J31: 自用不動產抵押貸款 | K31: 0 | L31: =IFERROR(致富性債務[[#This Row],[價值]]/致富性債務[[#Totals],[價值]],0) -> 0 | P31: 活壓力過大。
D32: =IFERROR(壓榨性債務[[#This Row],[價值]]/壓榨性債務[[#Totals],[價值]],0) -> 0 | J32: 投資性不動產抵押貸款 | K32: 0 | L32: =IFERROR(致富性債務[[#This Row],[價值]]/致富性債務[[#Totals],[價值]],0) -> 0 | P32: 2.若數據>50%，顯示出資產
B33: 合計 | C33: =SUBTOTAL(109,[價值]) -> 3435680 | E33: =SUBTOTAL(109,[月繳]) -> 86669 | J33: 信用貸款 | K33: 0 | L33: =IFERROR(致富性債務[[#This Row],[價值]]/致富性債務[[#Totals],[價值]],0) -> 0 | P33: 大部份是舉債購得的。
J34: 分期付款 | K34: 0 | L34: =IFERROR(致富性債務[[#This Row],[價值]]/致富性債務[[#Totals],[價值]],0) -> 0
J35: 保單貸款 | K35: 0 | L35: =IFERROR(致富性債務[[#This Row],[價值]]/致富性債務[[#Totals],[價值]],0) -> 0 | P35: ●生活週轉金充裕度 | Q35: =流動性資產[[#Totals],[價值]]/'現金流量表 (手打、整合)'!E7 -> #NAME? | R35: ≧300%
J36: 合計 | K36: =SUBTOTAL(109,[價值]) -> 0 | P36: 1.數據<300%，太冒險；數據>600%
P37: 又太保守，建議年輕者以300%為佳
P38: ，年長者或退休者以6為佳。
P40: 2.數據>3時，建議可將多餘資金挪做
P41: 其他相對安全的投資工具(例如債券..等)

Sheet 現金流量表(連動)
D2: 年份 | E2: 估值 | F2: 初始 | G2: 45839 | H2: =EDATE(G2,1) -> 45870 | I2: =EDATE(H2,1) -> 45901 | J2: =EDATE(I2,1) -> 45931 | K2: =EDATE(J2,1) -> 45962 | L2: =EDATE(K2,1) -> 45992 | M2: =EDATE(L2,1) -> 46023 | N2: =EDATE(M2,1) -> 46054 | O2: =EDATE(N2,1) -> 46082 | ... S2: =EDATE(R2,1) -> 46204
D3: 持有資金 | F3: 0 | G3: =F3+G4 -> -89753 | H3: =G3+H4 -> -176930 | I3: =H3+I4 -> -176930 | J3: =I3+J4 -> -176930 | K3: =J3+K4 -> -176930 | L3: =K3+L4 -> -176930 | M3: =L3+M4 -> -176930 | N3: =M3+N4 -> -176930 | ... S3: =R3+S4 -> -176930
D4: 現金流 | G4: =G5+G70+G22 -> -89753 | H4: =H5+H70+H22 -> -87177 | I4: =I5+I70+I22 -> 0 | J4: =J5+J70+J22 -> 0 | K4: =K5+K70+K22 -> 0 | L4: =L5+L70+L22 -> 0 | M4: =M5+M70+M22 -> 0 | N4: =N5+N70+N22 -> 0 | ... S4: =S5+S70+S22 -> 0
B5: 收入 | D5: 總計 | E5: =SUM(E6+E9+E12+E15+E20) -> 76000 | G5: =SUM(G6+G9+G12+G15+G20) -> 0 | H5: =SUM(H6+H9+H12+H15+H20) -> 20000 | I5: =SUM(I6+I9+I12+I15+I20) -> 0 | J5: =SUM(J6+J9+J12+J15+J20) -> 0 | K5: =SUM(K6+K9+K12+K15+K20) -> 0 | L5: =SUM(L6+L9+L12+L15+L20) -> 0 | M5: =SUM(M6+M9+M12+M15+M20) -> 0 | N5: =SUM(N6+N9+N12+N15+N20) -> 0 | ... S5: =SUM(S6+S9+S12+S15+S20) -> 0
D6: 本業 | E6: 76000 | G6: =SUMIFS(記帳區!$F:$F,記帳區!$K:$K,">=" & EOMONTH(G2,-1) + 1,記帳區!$K:$K,"<=" & EOMONTH(G2, 0),記帳區!$D:$D,$D6) -> 0 | H6: =SUMIFS(記帳區!$F:$F,記帳區!$K:$K,">=" & EOMONTH(H2,-1) + 1,記帳區!$K:$K,"<=" & EOMONTH(H2, 0),記帳區!$D:$D,$D6) -> 0 | I6: =SUMIFS(記帳區!$F:$F,記帳區!$K:$K,">=" & EOMONTH(I2,-1) + 1,記帳區!$K:$K,"<=" & EOMONTH(I2, 0),記帳區!$D:$D,$D6) -> 0 | J6: =SUMIFS(記帳區!$F:$F,記帳區!$K:$K,">=" & EOMONTH(J2,-1) + 1,記帳區!$K:$K,"<=" & EOMONTH(J2, 0),記帳區!$D:$D,$D6) -> 0 | K6: =SUMIFS(記帳區!$F:$F,記帳區!$K:$K,">=" & EOMONTH(K2,-1) + 1,記帳區!$K:$K,"<=" & EOMONTH(K2, 0),記帳區!$D:$D,$D6) -> 0 | L6: =SUMIFS(記帳區!$F:$F,記帳區!$K:$K,">=" & EOMONTH(L2,-1) + 1,記帳區!$K:$K,"<=" & EOMONTH(L2, 0),記帳區!$D:$D,$D6) -> 0 | M6: =SUMIFS(記帳區!$F:$F,記帳區!$K:$K,">=" & EOMONTH(M2,-1) + 1,記帳區!$K:$K,"<=" & EOMONTH(M2, 0),記帳區!$D:$D,$D6) -> 0 | N6: =SUMIFS(記帳區!$F:$F,記帳區!$K:$K,">=" & EOMONTH(N2,-1) + 1,記帳區!$K:$K,"<=" & EOMONTH(N2, 0),記帳區!$D:$D,$D6) -> 0 | ... S6: =SUMIFS(記帳區!$F:$F,記帳區!$K:$K,">=" & EOMONTH(S2,-1) + 1,記帳區!$K:$K,"<=" & EOMONTH(S2, 0),記帳區!$D:$D,$D6) -> 0
D7: 薪資 | G7: =SUMIFS(記帳區!$F:$F,記帳區!$K:$K,">=" & EOMONTH(G2,-1) + 1,記帳區!$K:$K,"<=" & EOMONTH(G2, 0),記帳區!$E:$E,$D7) -> 71244 | H7: =SUMIFS(記帳區!$F:$F,記帳區!$K:$K,">=" & EOMONTH(H$2,-1) + 1,記帳區!$K:$K,"<=" & EOMONTH(H$2, 0),記帳區!$E:$E,$D7) -> 71244 | I7: =SUMIFS(記帳區!$F:$F,記帳區!$K:$K,">=" & EOMONTH(I$2,-1) + 1,記帳區!$K:$K,"<=" & EOMONTH(I$2, 0),記帳區!$E:$E,$D7) -> 0 | J7: =SUMIFS(記帳區!$F:$F,記帳區!$K:$K,">=" & EOMONTH(J$2,-1) + 1,記帳區!$K:$K,"<=" & EOMONTH(J$2, 0),記帳區!$E:$E,$D7) -> 0 | K7: =SUMIFS(記帳區!$F:$F,記帳區!$K:$K,">=" & EOMONTH(K$2,-1) + 1,記帳區!$K:$K,"<=" & EOMONTH(K$2, 0),記帳區!$E:$E,$D7) -> 0 | L7: =SUMIFS(記帳區!$F:$F,記帳區!$K:$K,">=" & EOMONTH(L$2,-1) + 1,記帳區!$K:$K,"<=" & EOMONTH(L$2, 0),記帳區!$E:$E,$D7) -> 0 | M7: =SUMIFS(記帳區!$F:$F,記帳區!$K:$K,">=" & EOMONTH(M$2,-1) + 1,記帳區!$K:$K,"<=" & EOMONTH(M$2, 0),記帳區!$E:$E,$D7) -> 0 | N7: =SUMIFS(記帳區!$F:$F,記帳區!$K:$K,">=" & EOMONTH(N$2,-1) + 1,記帳區!$K:$K,"<=" & EOMONTH(N$2, 0),記帳區!$E:$E,$D7) -> 0 | O7: =SUMIFS(記帳區!$F:$F,記帳區!$K:$K,">=" & EOMONTH(O$2,-1) + 1,記帳區!$K:$K,"<=" & EOMONTH(O$2, 0),記帳區!$E:$E,$D7) -> 0 | ... S7: =SUMIFS(記帳區!$F:$F,記帳區!$K:$K,">=" & EOMONTH(S$2,-1) + 1,記帳區!$K:$K,"<=" & EOMONTH(S$2, 0),記帳區!$E:$E,$D7) -> 0
D8: 加班費 | G8: =SUMIFS(記帳區!$F:$F,記帳區!$K:$K,">=" & EOMONTH($G$2,-1) + 1,記帳區!$K:$K,"<=" & EOMONTH($G$2, 0),記帳區!$E:$E,$D8) -> 15000 | H8: =SUMIFS(記帳區!$F:$F,記帳區!$K:$K,">=" & EOMONTH(H$2,-1) + 1,記帳區!$K:$K,"<=" & EOMONTH(H$2, 0),記帳區!$E:$E,$D8) -> 15000 | I8: =SUMIFS(記帳區!$F:$F,記帳區!$K:$K,">=" & EOMONTH(I$2,-1) + 1,記帳區!$K:$K,"<=" & EOMONTH(I$2, 0),記帳區!$E:$E,$D8) -> 0 | J8: =SUMIFS(記帳區!$F:$F,記帳區!$K:$K,">=" & EOMONTH(J$2,-1) + 1,記帳區!$K:$K,"<=" & EOMONTH(J$2, 0),記帳區!$E:$E,$D8) -> 0 | K8: =SUMIFS(記帳區!$F:$F,記帳區!$K:$K,">=" & EOMONTH(K$2,-1) + 1,記帳區!$K:$K,"<=" & EOMONTH(K$2, 0),記帳區!$E:$E,$D8) -> 0 | L8: =SUMIFS(記帳區!$F:$F,記帳區!$K:$K,">=" & EOMONTH(L$2,-1) + 1,記帳區!$K:$K,"<=" & EOMONTH(L$2, 0),記帳區!$E:$E,$D8) -> 0 | M8: =SUMIFS(記帳區!$F:$F,記帳區!$K:$K,">=" & EOMONTH(M$2,-1) + 1,記帳區!$K:$K,"<=" & EOMONTH(M$2, 0),記帳區!$E:$E,$D8) -> 0 | N8: =SUMIFS(記帳區!$F:$F,記帳區!$K:$K,">=" & EOMONTH(N$2,-1) + 1,記帳區!$K:$K,"<=" & EOMONTH(N$2, 0),記帳區!$E:$E,$D8) -> 0 | O8: =SUMIFS(記帳區!$F:$F,記帳區!$K:$K,">=" & EOMONTH(O$2,-1) + 1,記帳區!$K:$K,"<=" & EOMONTH(O$2, 0),記帳區!$E:$E,$D8) -> 0 | ... S8: =SUMIFS(記帳區!$F:$F,記帳區!$K:$K,">=" & EOMONTH(S$2,-1) + 1,記帳區!$K:$K,"<=" & EOMONTH(S$2, 0),記帳區!$E:$E,$D8) -> 0
D9: 副業 | G9: =SUMIFS(記帳區!$F:$F,記帳區!$K:$K,">=" & EOMONTH(G2,-1) + 1,記帳區!$K:$K,"<=" & EOMONTH(G2, 0),記帳區!$D:$D,$D9) -> 0 | H9: =SUMIFS(記帳區!$F:$F,記帳區!$K:$K,">=" & EOMONTH(H2,-1) + 1,記帳區!$K:$K,"<=" & EOMONTH(H2, 0),記帳區!$D:$D,$D9) -> 0 | I9: =SUMIFS(記帳區!$F:$F,記帳區!$K:$K,">=" & EOMONTH(I2,-1) + 1,記帳區!$K:$K,"<=" & EOMONTH(I2, 0),記帳區!$D:$D,$D9) -> 0 | J9: =SUMIFS(記帳區!$F:$F,記帳區!$K:$K,">=" & EOMONTH(J2,-1) + 1,記帳區!$K:$K,"<=" & EOMONTH(J2, 0),記帳區!$D:$D,$D9) -> 0 | K9: =SUMIFS(記帳區!$F:$F,記帳區!$K:$K,">=" & EOMONTH(K2,-1) + 1,記帳區!$K:$K,"<=" & EOMONTH(K2, 0),記帳區!$D:$D,$D9) -> 0 | L9: =SUMIFS(記帳區!$F:$F,記帳區!$K:$K,">=" & EOMONTH(L2,-1) + 1,記帳區!$K:$K,"<=" & EOMONTH(L2, 0),記帳區!$D:$D,$D9) -> 0 | M9: =SUMIFS(記帳區!$F:$F,記帳區!$K:$K,">=" & EOMONTH(M2,-1) + 1,記帳區!$K:$K,"<=" & EOMONTH(M2, 0),記帳區!$D:$D,$D9) -> 0 | N9: =SUMIFS(記帳區!$F:$F,記帳區!$K:$K,">=" & EOMONTH(N2,-1) + 1,記帳區!$K:$K,"<=" & EOMONTH(N2, 0),記帳區!$D:$D,$D9) -> 0 | ... S9: =SUMIFS(記帳區!$F:$F,記帳區!$K:$K,">=" & EOMONTH(S2,-1) + 1,記帳區!$K:$K,"<=" & EOMONTH(S2, 0),記帳區!$D:$D,$D9) -> 0
G10: =SUMIFS(記帳區!$F:$F,記帳區!$K:$K,">=" & EOMONTH($G$2,-1) + 1,記帳區!$K:$K,"<=" & EOMONTH($G$2, 0),記帳區!$E:$E,$D10) -> 0 | H10: =SUMIFS(記帳區!$F:$F,記帳區!$K:$K,">=" & EOMONTH(H$2,-1) + 1,記帳區!$K:$K,"<=" & EOMONTH(H$2, 0),記帳區!$E:$E,$D10) -> 0 | I10: =SUMIFS(記帳區!$F:$F,記帳區!$K:$K,">=" & EOMONTH(I$2,-1) + 1,記帳區!$K:$K,"<=" & EOMONTH(I$2, 0),記帳區!$E:$E,$D10) -> 0 | J10: =SUMIFS(記帳區!$F:$F,記帳區!$K:$K,">=" & EOMONTH(J$2,-1) + 1,記帳區!$K:$K,"<=" & EOMONTH(J$2, 0),記帳區!$E:$E,$D10) -> 0 | K10: =SUMIFS(記帳區!$F:$F,記帳區!$K:$K,">=" & EOMONTH(K$2,-1) + 1,記帳區!$K:$K,"<=" & EOMONTH(K$2, 0),記帳區!$E:$E,$D10) -> 0 | L10: =SUMIFS(記帳區!$F:$F,記帳區!$K:$K,">=" & EOMONTH(L$2,-1) + 1,記帳區!$K:$K,"<=" & EOMONTH(L$2, 0),記帳區!$E:$E,$D10) -> 0 | M10: =SUMIFS(記帳區!$F:$F,記帳區!$K:$K,">=" & EOMONTH(M$2,-1) + 1,記帳區!$K:$K,"<=" & EOMONTH(M$2, 0),記帳區!$E:$E,$D10) -> 0 | N10: =SUMIFS(記帳區!$F:$F,記帳區!$K:$K,">=" & EOMONTH(N$2,-1) + 1,記帳區!$K:$K,"<=" & EOMONTH(N$2, 0),記帳區!$E:$E,$D10) -> 0 | O10: =SUMIFS(記帳區!$F:$F,記帳區!$K:$K,">=" & EOMONTH(O$2,-1) + 1,記帳區!$K:$K,"<=" & EOMONTH(O$2, 0),記帳區!$E:$E,$D10) -> 0 | ... S10: =SUMIFS(記帳區!$F:$F,記帳區!$K:$K,">=" & EOMONTH(S$2,-1) + 1,記帳區!$K:$K,"<=" & EOMONTH(S$2, 0),記帳區!$E:$E,$D10) -> 0
G11: =SUMIFS(記帳區!$F:$F,記帳區!$K:$K,">=" & EOMONTH($G$2,-1) + 1,記帳區!$K:$K,"<=" & EOMONTH($G$2, 0),記帳區!$E:$E,$D11) -> 0 | H11: =SUMIFS(記帳區!$F:$F,記帳區!$K:$K,">=" & EOMONTH(H$2,-1) + 1,記帳區!$K:$K,"<=" & EOMONTH(H$2, 0),記帳區!$E:$E,$D11) -> 0 | I11: =SUMIFS(記帳區!$F:$F,記帳區!$K:$K,">=" & EOMONTH(I$2,-1) + 1,記帳區!$K:$K,"<=" & EOMONTH(I$2, 0),記帳區!$E:$E,$D11) -> 0 | J11: =SUMIFS(記帳區!$F:$F,記帳區!$K:$K,">=" & EOMONTH(J$2,-1) + 1,記帳區!$K:$K,"<=" & EOMONTH(J$2, 0),記帳區!$E:$E,$D11) -> 0 | K11: =SUMIFS(記帳區!$F:$F,記帳區!$K:$K,">=" & EOMONTH(K$2,-1) + 1,記帳區!$K:$K,"<=" & EOMONTH(K$2, 0),記帳區!$E:$E,$D11) -> 0 | L11: =SUMIFS(記帳區!$F:$F,記帳區!$K:$K,">=" & EOMONTH(L$2,-1) + 1,記帳區!$K:$K,"<=" & EOMONTH(L$2, 0),記帳區!$E:$E,$D11) -> 0 | M11: =SUMIFS(記帳區!$F:$F,記帳區!$K:$K,">=" & EOMONTH(M$2,-1) + 1,記帳區!$K:$K,"<=" & EOMONTH(M$2, 0),記帳區!$E:$E,$D11) -> 0 | N11: =SUMIFS(記帳區!$F:$F,記帳區!$K:$K,">=" & EOMONTH(N$2,-1) + 1,記帳區!$K:$K,"<=" & EOMONTH(N$2, 0),記帳區!$E:$E,$D11) -> 0 | O11: =SUMIFS(記帳區!$F:$F,記帳區!$K:$K,">=" & EOMONTH(O$2,-1) + 1,記帳區!$K:$K,"<=" & EOMONTH(O$2, 0),記帳區!$E:$E,$D11) -> 0 | ... S11: =SUMIFS(記帳區!$F:$F,記帳區!$K:$K,">=" & EOMONTH(S$2,-1) + 1,記帳區!$K:$K,"<=" & EOMONTH(S$2, 0),記帳區!$E:$E,$D11) -> 0
D12: 投資盈利 | G12: =SUMIFS(記帳區!$F:$F,記帳區!$K:$K,">=" & EOMONTH(G2,-1) + 1,記帳區!$K:$K,"<=" & EOMONTH(G2, 0),記帳區!$D:$D,$D12) -> 0 | H12: =SUMIFS(記帳區!$F:$F,記帳區!$K:$K,">=" & EOMONTH(H2,-1) + 1,記帳區!$K:$K,"<=" & EOMONTH(H2, 0),記帳區!$D:$D,$D12) -> 0 | I12: =SUMIFS(記帳區!$F:$F,記帳區!$K:$K,">=" & EOMONTH(I2,-1) + 1,記帳區!$K:$K,"<=" & EOMONTH(I2, 0),記帳區!$D:$D,$D12) -> 0 | J12: =SUMIFS(記帳區!$F:$F,記帳區!$K:$K,">=" & EOMONTH(J2,-1) + 1,記帳區!$K:$K,"<=" & EOMONTH(J2, 0),記帳區!$D:$D,$D12) -> 0 | K12: =SUMIFS(記帳區!$F:$F,記帳區!$K:$K,">=" & EOMONTH(K2,-1) + 1,記帳區!$K:$K,"<=" & EOMONTH(K2, 0),記帳區!$D:$D,$D12) -> 0 | L12: =SUMIFS(記帳區!$F:$F,記帳區!$K:$K,">=" & EOMONTH(L2,-1) + 1,記帳區!$K:$K,"<=" & EOMONTH(L2, 0),記帳區!$D:$D,$D12) -> 0 | M12: =SUMIFS(記帳區!$F:$F,記帳區!$K:$K,">=" & EOMONTH(M2,-1) + 1,記帳區!$K:$K,"<=" & EOMONTH(M2, 0),記帳區!$D:$D,$D12) -> 0 | N12: =SUMIFS(記帳區!$F:$F,記帳區!$K:$K,">=" & EOMONTH(N2,-1) + 1,記帳區!$K:$K,"<=" & EOMONTH(N2, 0),記帳區!$D:$D,$D12) -> 0 | ... S12: =SUMIFS(記帳區!$F:$F,記帳區!$K:$K,">=" & EOMONTH(S2,-1) + 1,記帳區!$K:$K,"<=" & EOMONTH(S2, 0),記帳區!$D:$D,$D12) -> 0
